Workbook

Sheet 읽기전
A1: 읽기 전에
A3: 제목 | B3: 전국 「지역명+진료과」 키워드 3년 검색수요 분석
A4: 출처 | B4: 네이버 데이터랩 검색어트렌드 API (PlayMCP NaverSearch-datalab_search)
A5: 대상 기간 | B5: 2023-09 ~ 2026-08 (36개월, 월간)
A6: 수집일 | B6: 2026-09-09
A7: 키워드 수 | B7: 83개 (API 요청 21회, 모든 요청에 앵커 「서울피부과」 동봉)
A9: ■ 단위 — 반드시 먼저 읽을 것
B10: 이 파일의 모든 수치는 「월간 검색량(회)」이 아니라 상대지수다.
B11: 데이터랩은 절대 검색 횟수를 공개하지 않고, 요청 안의 최댓값을 100으로 둔 비율만 준다.
B12: 기준: 앵커 「서울피부과」의 36개월 평균 = 100. 지수 200이면 서울피부과의 약 2배가 검색됐다는 뜻이다.
B13: 절대 조회수·입찰가가 필요하면 네이버 검색광고 키워드도구(월간검색수 PC/모바일)를 별도로 붙여야 한다.
A15: ■ 요청 간 스케일을 맞춘 방법
B16: 데이터랩은 요청마다 최댓값을 100으로 재조정하므로 요청이 다르면 값을 비교할 수 없다 (응답 = c × 실제검색량, c는 요청마다 다름).
B17: 21번의 요청 전부에 앵커 「서울피부과」를 한 자리 고정으로 넣고, 각 요청 응답을 그 요청의 앵커 36개월 평균으로 나눠 c를 소거했다.
B18: 결과: 지수 = 실제검색량 ÷ 서울피부과 평균검색량 × 100. 앵커 자신의 시계열은 보존되므로 수준 비교와 추이 비교를 동시에 할 수 있다.
A20: ■ 연차 구분
B21: 1년차 = 2023.09–2024.08 | 2년차 = 2024.09–2025.08 | 3년차 = 2025.09–2026.08 | 3년 변화 = 3년차 ÷ 1년차 − 1
A23: ■ 시트 구성
B24: 요약_진료과 / 요약_지역 — 7대 도시·7개 진료과 합산 (수식)
B25: 수요검증 — 「환자 검색 수요가 실제로 줄었나」에 답하는 4개 묶음 비교. 대조군은 의료와 무관한 기준선
B26: TOP3 — 진료과별 대표 키워드 상위 3개
B27: 매트릭스 — 7개 진료과 × 7대 도시 규모·변화율
B28: 키워드지표 — 78개 키워드 전체 지표 (전부 월별지수를 참조하는 수식)
B29: 월별지수 — 78개 키워드 × 36개월 원지수 ★ 이 시트가 유일한 입력값이다
B30: 계절지수 / 계절_월별 — 월별 성수기·비수기 (연평균 100 기준)
B31: 원자료 — 데이터랩 API 원응답 98행 (앵커 포함, 정규화 전)
A33: ■ 편집 안내
B34: 값을 직접 넣는 시트는 「월별지수」와 「원자료」뿐이다. 나머지 시트는 전부 수식이므로 덮어쓰지 말 것.
B35: 키워드를 추가하려면 월별지수 맨 아래에 행을 추가하고 키워드지표의 마지막 행 수식을 아래로 복사하면 된다.
A37: ■ 한계
B38: ① 절대 검색량이 아니다. ② PC+모바일 합산·전 연령/성별 값이라 세그먼트 분해 불가.
B39: ③ 「광주」는 광주광역시와 경기 광주시가 섞인다. 광주 수치는 별도 검증 후 사용을 권한다.
B40: ④ 지역명 키워드는 표본이 작아 단발 이슈에 크게 흔들린다 (키워드지표의 변동계수·스파이크 열로 확인).
B41: ⑤ 데이터랩은 일정 기준 미만 검색량을 0으로 처리하므로 초소형 키워드는 과소 집계될 수 있다.
B42: ⑥ 검색 수요만 다루며 경쟁 강도·입찰가·전환율·실제 내원은 포함하지 않는다.
B43: ⑦ 데이터랩 지수가 네이버 전체 트래픽 변화를 보정하는지는 공식 문서로 확인하지 못했다(문서 접근 불가).
B44: 「수요검증」 시트의 대조군(날씨·지하철·환율·로또)이 그 확인을 대신한 간접 검증이다.
A46: ■ 의료광고법
B47: 이 문서는 검색 수요 통계만 다루며 치료 효과·전후 비교·최상급 표현을 포함하지 않는다.

Sheet 월별지수
A1: 키워드 | B1: 분류 | C1: 2023-09 | D1: 2023-10 | E1: 2023-11 | F1: 2023-12 | G1: 2024-01 | H1: 2024-02 | I1: 2024-03 | J1: 2024-04 | K1: 2024-05 | L1: 2024-06 | M1: 2024-07 | N1: 2024-08 | O1: 2024-09 | P1: 2024-10 | Q1: 2024-11 | R1: 2024-12 | S1: 2025-01 | T1: 2025-02 | U1: 2025-03 | V1: 2025-04 | W1: 2025-05 | X1: 2025-06 | Y1: 2025-07 | Z1: 2025-08 | AA1: 2025-09 | AB1: 2025-10 | AC1: 2025-11 | AD1: 2025-12 | AE1: 2026-01 | AF1: 2026-02 | AG1: 2026-03 | AH1: 2026-04 | AI1: 2026-05 | AJ1: 2026-06 | AK1: 2026-07 | AL1: 2026-08
A2: 서울치과 | B2: 지역명+진료과 | C2: 85.24 | D2: 95.54 | E2: 89.32 | F2: 95.56 | G2: 104.76 | H2: 97.13 | I2: 92.54 | J2: 91.96 | K2: 100.19 | L2: 87.33 | M2: 97.1 | N2: 97.55 | O2: 81.42 | P2: 81.95 | Q2: 89.01 | R2: 91.79 | S2: 93.75 | T2: 93.76 | U2: 94.15 | V2: 81.54 | W2: 83.91 | X2: 78.11 | Y2: 86.38 | Z2: 82.41 | AA2: 73.6 | AB2: 76.52 | AC2: 69.35 | AD2: 87.81 | AE2: 90.47 | AF2: 78.75 | AG2: 81 | AH2: 72.6 | AI2: 80.13 | AJ2: 76.53 | AK2: 82.38 | AL2: 86.99
A3: 부산치과 | B3: 지역명+진료과 | C3: 45.59 | D3: 45.5 | E3: 72.2 | F3: 104.82 | G3: 129.75 | H3: 100.91 | I3: 112.55 | J3: 197.73 | K3: 127.18 | L3: 76.29 | M3: 94.35 | N3: 86.53 | O3: 68.42 | P3: 51.43 | Q3: 57.41 | R3: 83.7 | S3: 60.24 | T3: 75.73 | U3: 154.73 | V3: 105.46 | W3: 78.69 | X3: 60.49 | Y3: 232.01 | Z3: 135 | AA3: 96.73 | AB3: 64.04 | AC3: 45.86 | AD3: 58.87 | AE3: 68.9 | AF3: 67.09 | AG3: 140.41 | AH3: 54.31 | AI3: 52.43 | AJ3: 65.59 | AK3: 132.82 | AL3: 113.12
A4: 대구치과 | B4: 지역명+진료과 | C4: 130.59 | D4: 195.55 | E4: 237.22 | F4: 146.81 | G4: 96.32 | H4: 150.86 | I4: 139.17 | J4: 99.63 | K4: 67.83 | L4: 51.72 | M4: 46.45 | N4: 80.34 | O4: 75.52 | P4: 68.64 | Q4: 64.66 | R4: 79.54 | S4: 110 | T4: 80.22 | U4: 215.8 | V4: 205.13 | W4: 172.25 | X4: 248.32 | Y4: 156.35 | Z4: 141.85 | AA4: 159.69 | AB4: 186.83 | AC4: 58.09 | AD4: 80.46 | AE4: 68.69 | AF4: 75.91 | AG4: 162.63 | AH4: 48.87 | AI4: 85.3 | AJ4: 79.56 | AK4: 159.14 | AL4: 173.94
A5: 인천치과 | B5: 지역명+진료과 | C5: 57.67 | D5: 81.93 | E5: 85.77 | F5: 77.48 | G5: 56.54 | H5: 64.44 | I5: 49.26 | J5: 63.08 | K5: 78.35 | L5: 56.45 | M5: 55.69 | N5: 53.38 | O5: 41.28 | P5: 55.52 | Q5: 57.1 | R5: 65.84 | S5: 60.43 | T5: 81.59 | U5: 75.53 | V5: 52.91 | W5: 66.33 | X5: 86.72 | Y5: 108.14 | Z5: 69.9 | AA5: 71.12 | AB5: 56.09 | AC5: 51.56 | AD5: 81.19 | AE5: 87.93 | AF5: 35.75 | AG5: 38.01 | AH5: 33.57 | AI5: 46.89 | AJ5: 48.51 | AK5: 60.97 | AL5: 83.08
A6: 광주치과 | B6: 지역명+진료과 | C6: 40.15 | D6: 41.63 | E6: 49.65 | F6: 52.68 | G6: 57.26 | H6: 84.73 | I6: 69.78 | J6: 50 | K6: 49.97 | L6: 47.61 | M6: 53.78 | N6: 205.7 | O6: 66.4 | P6: 63.83 | Q6: 59.13 | R6: 64.25 | S6: 92.68 | T6: 99.7 | U6: 76.45 | V6: 63.86 | W6: 91.68 | X6: 89.67 | Y6: 54.1 | Z6: 51.27 | AA6: 61.32 | AB6: 84.19 | AC6: 71.48 | AD6: 76.47 | AE6: 48.05 | AF6: 58.49 | AG6: 60.42 | AH6: 56.04 | AI6: 55.26 | AJ6: 43.52 | AK6: 78.23 | AL6: 63.04
A7: 대전치과 | B7: 지역명+진료과 | C7: 58.06 | D7: 78.17 | E7: 88.42 | F7: 70.01 | G7: 78.41 | H7: 93.57 | I7: 107.39 | J7: 82.19 | K7: 78.48 | L7: 81.44 | M7: 85.72 | N7: 112.89 | O7: 92.31 | P7: 90.62 | Q7: 91.42 | R7: 121.44 | S7: 167.5 | T7: 112.94 | U7: 156.75 | V7: 144.04 | W7: 159.2 | X7: 141.41 | Y7: 145.62 | Z7: 126.14 | AA7: 134.07 | AB7: 130.34 | AC7: 122.45 | AD7: 117.84 | AE7: 85.92 | AF7: 77.24 | AG7: 107.92 | AH7: 78.43 | AI7: 92.75 | AJ7: 70.87 | AK7: 97.6 | AL7: 93.67
A8: 울산치과 | B8: 지역명+진료과 | C8: 56.77 | D8: 77.29 | E8: 92.94 | F8: 76.05 | G8: 62.07 | H8: 67.39 | I8: 191.48 | J8: 131.38 | K8: 94.64 | L8: 73.61 | M8: 81.48 | N8: 69.91 | O8: 54.9 | P8: 65.34 | Q8: 58.21 | R8: 48.88 | S8: 64.36 | T8: 138.31 | U8: 186.81 | V8: 227.76 | W8: 157.06 | X8: 98.48 | Y8: 147.99 | Z8: 106.62 | AA8: 82.2 | AB8: 84.92 | AC8: 61.96 | AD8: 72.27 | AE8: 75.94 | AF8: 61.62 | AG8: 65.12 | AH8: 57.72 | AI8: 93.68 | AJ8: 47.8 | AK8: 47.59 | AL8: 79.65
A9: 서울한의원 | B9: 지역명+진료과 | C9: 27.21 | D9: 30.28 | E9: 25.09 | F9: 26.14 | G9: 29.15 | H9: 29.57 | I9: 27.11 | J9: 27.8 | K9: 32.56 | L9: 27.01 | M9: 30.25 | N9: 32.4 | O9: 29.93 | P9: 28.3 | Q9: 24.3 | R9: 23.76 | S9: 27.92 | T9: 25.09 | U9: 28.55 | V9: 25.19 | W9: 29.6 | X9: 29.77 | Y9: 27.88 | Z9: 29.98 | AA9: 27.49 | AB9: 29.07 | AC9: 22.5 | AD9: 22.07 | AE9: 25.79 | AF9: 23.93 | AG9: 22.94 | AH9: 24.11 | AI9: 27.1 | AJ9: 25.39 | AK9: 28.16 | AL9: 27.25
A10: 부산한의원 | B10: 지역명+진료과 | C10: 40.48 | D10: 112.45 | E10: 35.56 | F10: 23.3 | G10: 23.94 | H10: 25 | I10: 87.26 | J10: 90.59 | K10: 73.27 | L10: 74.73 | M10: 65.12 | N10: 43.85 | O10: 34.02 | P10: 27.44 | Q10: 27.74 | R10: 26.9 | S10: 25.62 | T10: 22.38 | U10: 27 | V10: 27.37 | W10: 31.35 | X10: 35.43 | Y10: 29.19 | Z10: 31.64 | AA10: 32.01 | AB10: 28.28 | AC10: 26.03 | AD10: 35.36 | AE10: 77.2 | AF10: 64.52 | AG10: 28.95 | AH10: 36.98 | AI10: 26.82 | AJ10: 27.87 | AK10: 32.42 | AL10: 28.03
A11: 대구한의원 | B11: 지역명+진료과 | C11: 32.4 | D11: 29.64 | E11: 48.79 | F11: 39.5 | G11: 38.04 | H11: 43.15 | I11: 58.2 | J11: 60.34 | K11: 83.93 | L11: 61.21 | M11: 56.71 | N11: 55.72 | O11: 36.86 | P11: 36.34 | Q11: 35.65 | R11: 54.03 | S11: 62.76 | T11: 50.89 | U11: 69.75 | V11: 61.72 | W11: 28.82 | X11: 26.66 | Y11: 45.24 | Z11: 46.96 | AA11: 35 | AB11: 28.48 | AC11: 23.94 | AD11: 32.79 | AE11: 51.95 | AF11: 41.87 | AG11: 32.3 | AH11: 38.23 | AI11: 31.68 | AJ11: 24.05 | AK11: 25.65 | AL11: 28.66
A12: 인천한의원 | B12: 지역명+진료과 | C12: 98.51 | D12: 117.93 | E12: 205.05 | F12: 111.12 | G12: 66.04 | H12: 65.49 | I12: 84.08 | J12: 87.97 | K12: 66.23 | L12: 57.19 | M12: 59.73 | N12: 51.06 | O12: 56.88 | P12: 44.24 | Q12: 36.88 | R12: 36.82 | S12: 40.56 | T12: 40.93 | U12: 43.56 | V12: 43.38 | W12: 46.23 | X12: 44.32 | Y12: 50.7 | Z12: 70.9 | AA12: 54.52 | AB12: 60.21 | AC12: 42.46 | AD12: 39.08 | AE12: 48.41 | AF12: 36.56 | AG12: 42.12 | AH12: 46.61 | AI12: 39.22 | AJ12: 31.27 | AK12: 34.35 | AL12: 28.99
A13: 광주한의원 | B13: 지역명+진료과 | C13: 19.82 | D13: 20.61 | E13: 16.93 | F13: 17.47 | G13: 20 | H13: 22.83 | I13: 22.64 | J13: 23.45 | K13: 20.31 | L13: 25.41 | M13: 23.83 | N13: 20.56 | O13: 40.53 | P13: 21.3 | Q13: 21.17 | R13: 18.82 | S13: 22.09 | T13: 29.33 | U13: 21.46 | V13: 17.15 | W13: 15.24 | X13: 21.24 | Y13: 19.34 | Z13: 29.66 | AA13: 27.43 | AB13: 44.15 | AC13: 16.74 | AD13: 16.75 | AE13: 16.6 | AF13: 19.58 | AG13: 20.84 | AH13: 24.13 | AI13: 25.47 | AJ13: 24.07 | AK13: 23.75 | AL13: 22.15
... A84: 대구산부인과 | B84: 기타진료과(참고) | C84: 54.74 | D84: 57.61 | E84: 48.66 | F84: 51.84 | G84: 55.23 | H84: 52.79 | I84: 54.85 | J84: 65.05 | K84: 57.81 | L84: 54.11 | M84: 57.96 | N84: 59.35 | O84: 60.84 | P84: 56.55 | Q84: 48.19 | R84: 50.91 | S84: 57.58 | T84: 50.81 | U84: 60.99 | V84: 67.9 | W84: 54.59 | X84: 52.22 | Y84: 53.05 | Z84: 61.84 | AA84: 51.08 | AB84: 61.33 | AC84: 44.01 | AD84: 49.27 | AE84: 48.41 | AF84: 48.27 | AG84: 50.56 | AH84: 56.99 | AI84: 56.95 | AJ84: 50.41 | AK84: 51.88 | AL84: 52.19

Sheet 계절_월별
A1: 키워드 | B1: 1 | C1: 2 | D1: 3 | E1: 4 | F1: 5 | G1: 6 | H1: 7 | I1: 8 | J1: 9 | K1: 10 | L1: 11 | M1: 12
A2: 서울치과 | B2: =IFERROR(AVERAGE(월별지수!G2,월별지수!S2,월별지수!AE2)/키워드지표!$C2*100,"") -> 110.84195 | C2: =IFERROR(AVERAGE(월별지수!H2,월별지수!T2,월별지수!AF2)/키워드지표!$C2*100,"") -> 103.42491 | D2: =IFERROR(AVERAGE(월별지수!I2,월별지수!U2,월별지수!AG2)/키워드지표!$C2*100,"") -> 102.6795 | E2: =IFERROR(AVERAGE(월별지수!J2,월별지수!V2,월별지수!AH2)/키워드지표!$C2*100,"") -> 94.394229 | F2: =IFERROR(AVERAGE(월별지수!K2,월별지수!W2,월별지수!AI2)/키워드지표!$C2*100,"") -> 101.35256 | G2: =IFERROR(AVERAGE(월별지수!L2,월별지수!X2,월별지수!AJ2)/키워드지표!$C2*100,"") -> 92.809232 | H2: =IFERROR(AVERAGE(월별지수!M2,월별지수!Y2,월별지수!AK2)/키워드지표!$C2*100,"") -> 101.97509 | I2: =IFERROR(AVERAGE(월별지수!N2,월별지수!Z2,월별지수!AL2)/키워드지표!$C2*100,"") -> 102.39282 | J2: =IFERROR(AVERAGE(월별지수!C2,월별지수!O2,월별지수!AA2)/키워드지표!$C2*100,"") -> 92.153942 | K2: =IFERROR(AVERAGE(월별지수!D2,월별지수!P2,월별지수!AB2)/키워드지표!$C2*100,"") -> 97.429016 | L2: =IFERROR(AVERAGE(월별지수!E2,월별지수!Q2,월별지수!AC2)/키워드지표!$C2*100,"") -> 95.000357 | M2: =IFERROR(AVERAGE(월별지수!F2,월별지수!R2,월별지수!AD2)/키워드지표!$C2*100,"") -> 105.5464
A3: 부산치과 | B3: =IFERROR(AVERAGE(월별지수!G3,월별지수!S3,월별지수!AE3)/키워드지표!$C3*100,"") -> 93.665677 | C3: =IFERROR(AVERAGE(월별지수!H3,월별지수!T3,월별지수!AF3)/키워드지표!$C3*100,"") -> 88.176388 | D3: =IFERROR(AVERAGE(월별지수!I3,월별지수!U3,월별지수!AG3)/키워드지표!$C3*100,"") -> 147.49631 | E3: =IFERROR(AVERAGE(월별지수!J3,월별지수!V3,월별지수!AH3)/키워드지표!$C3*100,"") -> 129.33644 | F3: =IFERROR(AVERAGE(월별지수!K3,월별지수!W3,월별지수!AI3)/키워드지표!$C3*100,"") -> 93.449348 | G3: =IFERROR(AVERAGE(월별지수!L3,월별지수!X3,월별지수!AJ3)/키워드지표!$C3*100,"") -> 73.215059 | H3: =IFERROR(AVERAGE(월별지수!M3,월별지수!Y3,월별지수!AK3)/키워드지표!$C3*100,"") -> 166.1236 | I3: =IFERROR(AVERAGE(월별지수!N3,월별지수!Z3,월별지수!AL3)/키워드지표!$C3*100,"") -> 121.06967 | J3: =IFERROR(AVERAGE(월별지수!C3,월별지수!O3,월별지수!AA3)/키워드지표!$C3*100,"") -> 76.243638 | K3: =IFERROR(AVERAGE(월별지수!D3,월별지수!P3,월별지수!AB3)/키워드지표!$C3*100,"") -> 58.23828 | L3: =IFERROR(AVERAGE(월별지수!E3,월별지수!Q3,월별지수!AC3)/키워드지표!$C3*100,"") -> 63.484215 | M3: =IFERROR(AVERAGE(월별지수!F3,월별지수!R3,월별지수!AD3)/키워드지표!$C3*100,"") -> 89.501384
A4: 대구치과 | B4: =IFERROR(AVERAGE(월별지수!G4,월별지수!S4,월별지수!AE4)/키워드지표!$C4*100,"") -> 75.005269 | C4: =IFERROR(AVERAGE(월별지수!H4,월별지수!T4,월별지수!AF4)/키워드지표!$C4*100,"") -> 83.727162 | D4: =IFERROR(AVERAGE(월별지수!I4,월별지수!U4,월별지수!AG4)/키워드지표!$C4*100,"") -> 141.16928 | E4: =IFERROR(AVERAGE(월별지수!J4,월별지수!V4,월별지수!AH4)/키워드지표!$C4*100,"") -> 96.447418 | F4: =IFERROR(AVERAGE(월별지수!K4,월별지수!W4,월별지수!AI4)/키워드지표!$C4*100,"") -> 88.744792 | G4: =IFERROR(AVERAGE(월별지수!L4,월별지수!X4,월별지수!AJ4)/키워드지표!$C4*100,"") -> 103.52977 | H4: =IFERROR(AVERAGE(월별지수!M4,월별지수!Y4,월별지수!AK4)/키워드지표!$C4*100,"") -> 98.713074 | I4: =IFERROR(AVERAGE(월별지수!N4,월별지수!Z4,월별지수!AL4)/키워드지표!$C4*100,"") -> 108.03777 | J4: =IFERROR(AVERAGE(월별지수!C4,월별지수!O4,월별지수!AA4)/키워드지표!$C4*100,"") -> 99.767266 | K4: =IFERROR(AVERAGE(월별지수!D4,월별지수!P4,월별지수!AB4)/키워드지표!$C4*100,"") -> 123.00621 | L4: =IFERROR(AVERAGE(월별지수!E4,월별지수!Q4,월별지수!AC4)/키워드지표!$C4*100,"") -> 98.177241 | M4: =IFERROR(AVERAGE(월별지수!F4,월별지수!R4,월별지수!AD4)/키워드지표!$C4*100,"") -> 83.674743
A5: 인천치과 | B5: =IFERROR(AVERAGE(월별지수!G5,월별지수!S5,월별지수!AE5)/키워드지표!$C5*100,"") -> 107.09153 | C5: =IFERROR(AVERAGE(월별지수!H5,월별지수!T5,월별지수!AF5)/키워드지표!$C5*100,"") -> 95.003976 | D5: =IFERROR(AVERAGE(월별지수!I5,월별지수!U5,월별지수!AG5)/키워드지표!$C5*100,"") -> 85.087263 | E5: =IFERROR(AVERAGE(월별지수!J5,월별지수!V5,월별지수!AH5)/키워드지표!$C5*100,"") -> 78.167326 | F5: =IFERROR(AVERAGE(월별지수!K5,월별지수!W5,월별지수!AI5)/키워드지표!$C5*100,"") -> 100.12137 | G5: =IFERROR(AVERAGE(월별지수!L5,월별지수!X5,월별지수!AJ5)/키워드지표!$C5*100,"") -> 100.18277 | H5: =IFERROR(AVERAGE(월별지수!M5,월별지수!Y5,월별지수!AK5)/키워드지표!$C5*100,"") -> 117.49377 | I5: =IFERROR(AVERAGE(월별지수!N5,월별지수!Z5,월별지수!AL5)/키워드지표!$C5*100,"") -> 107.8505 | J5: =IFERROR(AVERAGE(월별지수!C5,월별지수!O5,월별지수!AA5)/키워드지표!$C5*100,"") -> 88.887651 | K5: =IFERROR(AVERAGE(월별지수!D5,월별지수!P5,월별지수!AB5)/키워드지표!$C5*100,"") -> 101.15379 | L5: =IFERROR(AVERAGE(월별지수!E5,월별지수!Q5,월별지수!AC5)/키워드지표!$C5*100,"") -> 101.62256 | M5: =IFERROR(AVERAGE(월별지수!F5,월별지수!R5,월별지수!AD5)/키워드지표!$C5*100,"") -> 117.3375
A6: 광주치과 | B6: =IFERROR(AVERAGE(월별지수!G6,월별지수!S6,월별지수!AE6)/키워드지표!$C6*100,"") -> 97.674423 | C6: =IFERROR(AVERAGE(월별지수!H6,월별지수!T6,월별지수!AF6)/키워드지표!$C6*100,"") -> 119.8346 | D6: =IFERROR(AVERAGE(월별지수!I6,월별지수!U6,월별지수!AG6)/키워드지표!$C6*100,"") -> 101.94633 | E6: =IFERROR(AVERAGE(월별지수!J6,월별지수!V6,월별지수!AH6)/키워드지표!$C6*100,"") -> 83.815733 | F6: =IFERROR(AVERAGE(월별지수!K6,월별지수!W6,월별지수!AI6)/키워드지표!$C6*100,"") -> 97.137138 | G6: =IFERROR(AVERAGE(월별지수!L6,월별지수!X6,월별지수!AJ6)/키워드지표!$C6*100,"") -> 89.193812 | H6: =IFERROR(AVERAGE(월별지수!M6,월별지수!Y6,월별지수!AK6)/키워드지표!$C6*100,"") -> 91.817002 | I6: =IFERROR(AVERAGE(월별지수!N6,월별지수!Z6,월별지수!AL6)/키워드지표!$C6*100,"") -> 157.8709 | J6: =IFERROR(AVERAGE(월별지수!C6,월별지수!O6,월별지수!AA6)/키워드지표!$C6*100,"") -> 82.814933 | K6: =IFERROR(AVERAGE(월별지수!D6,월별지수!P6,월별지수!AB6)/키워드지표!$C6*100,"") -> 93.560531 | L6: =IFERROR(AVERAGE(월별지수!E6,월별지수!Q6,월별지수!AC6)/키워드지표!$C6*100,"") -> 88.92517 | M6: =IFERROR(AVERAGE(월별지수!F6,월별지수!R6,월별지수!AD6)/키워드지표!$C6*100,"") -> 95.409423
A7: 대전치과 | B7: =IFERROR(AVERAGE(월별지수!G7,월별지수!S7,월별지수!AE7)/키워드지표!$C7*100,"") -> 105.53059 | C7: =IFERROR(AVERAGE(월별지수!H7,월별지수!T7,월별지수!AF7)/키워드지표!$C7*100,"") -> 90.2394 | D7: =IFERROR(AVERAGE(월별지수!I7,월별지수!U7,월별지수!AG7)/키워드지표!$C7*100,"") -> 118.32589 | E7: =IFERROR(AVERAGE(월별지수!J7,월별지수!V7,월별지수!AH7)/키워드지표!$C7*100,"") -> 96.888332 | F7: =IFERROR(AVERAGE(월별지수!K7,월별지수!W7,월별지수!AI7)/키워드지표!$C7*100,"") -> 105.08574 | G7: =IFERROR(AVERAGE(월별지수!L7,월별지수!X7,월별지수!AJ7)/키워드지표!$C7*100,"") -> 93.411059 | H7: =IFERROR(AVERAGE(월별지수!M7,월별지수!Y7,월별지수!AK7)/키워드지표!$C7*100,"") -> 104.61373 | I7: =IFERROR(AVERAGE(월별지수!N7,월별지수!Z7,월별지수!AL7)/키워드지표!$C7*100,"") -> 105.81244 | J7: =IFERROR(AVERAGE(월별지수!C7,월별지수!O7,월별지수!AA7)/키워드지표!$C7*100,"") -> 90.460127 | K7: =IFERROR(AVERAGE(월별지수!D7,월별지수!P7,월별지수!AB7)/키워드지표!$C7*100,"") -> 95.132716 | L7: =IFERROR(AVERAGE(월별지수!E7,월별지수!Q7,월별지수!AC7)/키워드지표!$C7*100,"") -> 96.137867 | M7: =IFERROR(AVERAGE(월별지수!F7,월별지수!R7,월별지수!AD7)/키워드지표!$C7*100,"") -> 98.362104
A8: 울산치과 | B8: =IFERROR(AVERAGE(월별지수!G8,월별지수!S8,월별지수!AE8)/키워드지표!$C8*100,"") -> 74.488088 | C8: =IFERROR(AVERAGE(월별지수!H8,월별지수!T8,월별지수!AF8)/키워드지표!$C8*100,"") -> 98.391263 | D8: =IFERROR(AVERAGE(월별지수!I8,월별지수!U8,월별지수!AG8)/키워드지표!$C8*100,"") -> 163.21121 | E8: =IFERROR(AVERAGE(월별지수!J8,월별지수!V8,월별지수!AH8)/키워드지표!$C8*100,"") -> 153.43693 | F8: =IFERROR(AVERAGE(월별지수!K8,월별지수!W8,월별지수!AI8)/키워드지표!$C8*100,"") -> 127.12459 | G8: =IFERROR(AVERAGE(월별지수!L8,월별지수!X8,월별지수!AJ8)/키워드지표!$C8*100,"") -> 80.937469 | H8: =IFERROR(AVERAGE(월별지수!M8,월별지수!Y8,월별지수!AK8)/키워드지표!$C8*100,"") -> 101.97948 | I8: =IFERROR(AVERAGE(월별지수!N8,월별지수!Z8,월별지수!AL8)/키워드지표!$C8*100,"") -> 94.292131 | J8: =IFERROR(AVERAGE(월별지수!C8,월별지수!O8,월별지수!AA8)/키워드지표!$C8*100,"") -> 71.359674 | K8: =IFERROR(AVERAGE(월별지수!D8,월별지수!P8,월별지수!AB8)/키워드지표!$C8*100,"") -> 83.75539 | L8: =IFERROR(AVERAGE(월별지수!E8,월별지수!Q8,월별지수!AC8)/키워드지표!$C8*100,"") -> 78.441813 | M8: =IFERROR(AVERAGE(월별지수!F8,월별지수!R8,월별지수!AD8)/키워드지표!$C8*100,"") -> 72.581966
A9: 서울한의원 | B9: =IFERROR(AVERAGE(월별지수!G9,월별지수!S9,월별지수!AE9)/키워드지표!$C9*100,"") -> 101.39376 | C9: =IFERROR(AVERAGE(월별지수!H9,월별지수!T9,월별지수!AF9)/키워드지표!$C9*100,"") -> 96.167259 | D9: =IFERROR(AVERAGE(월별지수!I9,월별지수!U9,월별지수!AG9)/키워드지표!$C9*100,"") -> 96.180275 | E9: =IFERROR(AVERAGE(월별지수!J9,월별지수!V9,월별지수!AH9)/키워드지표!$C9*100,"") -> 94.351031 | F9: =IFERROR(AVERAGE(월별지수!K9,월별지수!W9,월별지수!AI9)/키워드지표!$C9*100,"") -> 109.22042 | G9: =IFERROR(AVERAGE(월별지수!L9,월별지수!X9,월별지수!AJ9)/키워드지표!$C9*100,"") -> 100.55748 | H9: =IFERROR(AVERAGE(월별지수!M9,월별지수!Y9,월별지수!AK9)/키워드지표!$C9*100,"") -> 105.58797 | I9: =IFERROR(AVERAGE(월별지수!N9,월별지수!Z9,월별지수!AL9)/키워드지표!$C9*100,"") -> 109.67771 | J9: =IFERROR(AVERAGE(월별지수!C9,월별지수!O9,월별지수!AA9)/키워드지표!$C9*100,"") -> 103.56274 | K9: =IFERROR(AVERAGE(월별지수!D9,월별지수!P9,월별지수!AB9)/키워드지표!$C9*100,"") -> 107.26044 | L9: =IFERROR(AVERAGE(월별지수!E9,월별지수!Q9,월별지수!AC9)/키워드지표!$C9*100,"") -> 87.974711 | M9: =IFERROR(AVERAGE(월별지수!F9,월별지수!R9,월별지수!AD9)/키워드지표!$C9*100,"") -> 88.066194
A10: 부산한의원 | B10: =IFERROR(AVERAGE(월별지수!G10,월별지수!S10,월별지수!AE10)/키워드지표!$C10*100,"") -> 102.35238 | C10: =IFERROR(AVERAGE(월별지수!H10,월별지수!T10,월별지수!AF10)/키워드지표!$C10*100,"") -> 90.359109 | D10: =IFERROR(AVERAGE(월별지수!I10,월별지수!U10,월별지수!AG10)/키워드지표!$C10*100,"") -> 115.63899 | E10: =IFERROR(AVERAGE(월별지수!J10,월별지수!V10,월별지수!AH10)/키워드지표!$C10*100,"") -> 125.10599 | F10: =IFERROR(AVERAGE(월별지수!K10,월별지수!W10,월별지수!AI10)/키워드지표!$C10*100,"") -> 106.13746 | G10: =IFERROR(AVERAGE(월별지수!L10,월별지수!X10,월별지수!AJ10)/키워드지표!$C10*100,"") -> 111.45728 | H10: =IFERROR(AVERAGE(월별지수!M10,월별지수!Y10,월별지수!AK10)/키워드지표!$C10*100,"") -> 102.33513 | I10: =IFERROR(AVERAGE(월별지수!N10,월별지수!Z10,월별지수!AL10)/키워드지표!$C10*100,"") -> 83.590779 | J10: =IFERROR(AVERAGE(월별지수!C10,월별지수!O10,월별지수!AA10)/키워드지표!$C10*100,"") -> 86.004972 | K10: =IFERROR(AVERAGE(월별지수!D10,월별지수!P10,월별지수!AB10)/키워드지표!$C10*100,"") -> 135.79734 | L10: =IFERROR(AVERAGE(월별지수!E10,월별지수!Q10,월별지수!AC10)/키워드지표!$C10*100,"") -> 72.132091 | M10: =IFERROR(AVERAGE(월별지수!F10,월별지수!R10,월별지수!AD10)/키워드지표!$C10*100,"") -> 69.088487
A11: 대구한의원 | B11: =IFERROR(AVERAGE(월별지수!G11,월별지수!S11,월별지수!AE11)/키워드지표!$C11*100,"") -> 117.66334 | C11: =IFERROR(AVERAGE(월별지수!H11,월별지수!T11,월별지수!AF11)/키워드지표!$C11*100,"") -> 104.68469 | D11: =IFERROR(AVERAGE(월별지수!I11,월별지수!U11,월별지수!AG11)/키워드지표!$C11*100,"") -> 123.43713 | E11: =IFERROR(AVERAGE(월별지수!J11,월별지수!V11,월별지수!AH11)/키워드지표!$C11*100,"") -> 123.4618 | F11: =IFERROR(AVERAGE(월별지수!K11,월별지수!W11,월별지수!AI11)/키워드지표!$C11*100,"") -> 111.24804 | G11: =IFERROR(AVERAGE(월별지수!L11,월별지수!X11,월별지수!AJ11)/키워드지표!$C11*100,"") -> 86.211871 | H11: =IFERROR(AVERAGE(월별지수!M11,월별지수!Y11,월별지수!AK11)/키워드지표!$C11*100,"") -> 98.285829 | I11: =IFERROR(AVERAGE(월별지수!N11,월별지수!Z11,월별지수!AL11)/키워드지표!$C11*100,"") -> 101.16448 | J11: =IFERROR(AVERAGE(월별지수!C11,월별지수!O11,월별지수!AA11)/키워드지표!$C11*100,"") -> 80.306519 | K11: =IFERROR(AVERAGE(월별지수!D11,월별지수!P11,월별지수!AB11)/키워드지표!$C11*100,"") -> 72.756183 | L11: =IFERROR(AVERAGE(월별지수!E11,월별지수!Q11,월별지수!AC11)/키워드지표!$C11*100,"") -> 83.481262 | M11: =IFERROR(AVERAGE(월별지수!F11,월별지수!R11,월별지수!AD11)/키워드지표!$C11*100,"") -> 97.298858
A12: 인천한의원 | B12: =IFERROR(AVERAGE(월별지수!G12,월별지수!S12,월별지수!AE12)/키워드지표!$C12*100,"") -> 87.349083 | C12: =IFERROR(AVERAGE(월별지수!H12,월별지수!T12,월별지수!AF12)/키워드지표!$C12*100,"") -> 80.562346 | D12: =IFERROR(AVERAGE(월별지수!I12,월별지수!U12,월별지수!AG12)/키워드지표!$C12*100,"") -> 95.658017 | E12: =IFERROR(AVERAGE(월별지수!J12,월별지수!V12,월별지수!AH12)/키워드지표!$C12*100,"") -> 100.27877 | F12: =IFERROR(AVERAGE(월별지수!K12,월별지수!W12,월별지수!AI12)/키워드지표!$C12*100,"") -> 85.471903 | G12: =IFERROR(AVERAGE(월별지수!L12,월별지수!X12,월별지수!AJ12)/키워드지표!$C12*100,"") -> 74.822509 | H12: =IFERROR(AVERAGE(월별지수!M12,월별지수!Y12,월별지수!AK12)/키워드지표!$C12*100,"") -> 81.579147 | I12: =IFERROR(AVERAGE(월별지수!N12,월별지수!Z12,월별지수!AL12)/키워드지표!$C12*100,"") -> 85.056746 | J12: =IFERROR(AVERAGE(월별지수!C12,월별지수!O12,월별지수!AA12)/키워드지표!$C12*100,"") -> 118.28046 | K12: =IFERROR(AVERAGE(월별지수!D12,월별지수!P12,월별지수!AB12)/키워드지표!$C12*100,"") -> 125.30785 | L12: =IFERROR(AVERAGE(월별지수!E12,월별지수!Q12,월별지수!AC12)/키워드지표!$C12*100,"") -> 160.25231 | M12: =IFERROR(AVERAGE(월별지수!F12,월별지수!R12,월별지수!AD12)/키워드지표!$C12*100,"") -> 105.38085
A13: 광주한의원 | B13: =IFERROR(AVERAGE(월별지수!G13,월별지수!S13,월별지수!AE13)/키워드지표!$C13*100,"") -> 86.648785 | C13: =IFERROR(AVERAGE(월별지수!H13,월별지수!T13,월별지수!AF13)/키워드지표!$C13*100,"") -> 105.91109 | D13: =IFERROR(AVERAGE(월별지수!I13,월별지수!U13,월별지수!AG13)/키워드지표!$C13*100,"") -> 95.87013 | E13: =IFERROR(AVERAGE(월별지수!J13,월별지수!V13,월별지수!AH13)/키워드지표!$C13*100,"") -> 95.554856 | F13: =IFERROR(AVERAGE(월별지수!K13,월별지수!W13,월별지수!AI13)/키워드지표!$C13*100,"") -> 90.069349 | G13: =IFERROR(AVERAGE(월별지수!L13,월별지수!X13,월별지수!AJ13)/키워드지표!$C13*100,"") -> 104.39786 | H13: =IFERROR(AVERAGE(월별지수!M13,월별지수!Y13,월별지수!AK13)/키워드지표!$C13*100,"") -> 98.78626 | I13: =IFERROR(AVERAGE(월별지수!N13,월별지수!Z13,월별지수!AL13)/키워드지표!$C13*100,"") -> 106.84111 | J13: =IFERROR(AVERAGE(월별지수!C13,월별지수!O13,월별지수!AA13)/키워드지표!$C13*100,"") -> 129.58701 | K13: =IFERROR(AVERAGE(월별지수!D13,월별지수!P13,월별지수!AB13)/키워드지표!$C13*100,"") -> 127.04918 | L13: =IFERROR(AVERAGE(월별지수!E13,월별지수!Q13,월별지수!AC13)/키워드지표!$C13*100,"") -> 80.974153 | M13: =IFERROR(AVERAGE(월별지수!F13,월별지수!R13,월별지수!AD13)/키워드지표!$C13*100,"") -> 78.310213
... A84: 대구산부인과 | B84: =IFERROR(AVERAGE(월별지수!G84,월별지수!S84,월별지수!AE84)/키워드지표!$C84*100,"") -> 98.369736 | C84: =IFERROR(AVERAGE(월별지수!H84,월별지수!T84,월별지수!AF84)/키워드지표!$C84*100,"") -> 92.662984 | D84: =IFERROR(AVERAGE(월별지수!I84,월별지수!U84,월별지수!AG84)/키워드지표!$C84*100,"") -> 101.52278 | E84: =IFERROR(AVERAGE(월별지수!J84,월별지수!V84,월별지수!AH84)/키워드지표!$C84*100,"") -> 115.88085 | F84: =IFERROR(AVERAGE(월별지수!K84,월별지수!W84,월별지수!AI84)/키워드지표!$C84*100,"") -> 103.32731 | G84: =IFERROR(AVERAGE(월별지수!L84,월별지수!X84,월별지수!AJ84)/키워드지표!$C84*100,"") -> 95.633625 | H84: =IFERROR(AVERAGE(월별지수!M84,월별지수!Y84,월별지수!AK84)/키워드지표!$C84*100,"") -> 99.379489 | I84: =IFERROR(AVERAGE(월별지수!N84,월별지수!Z84,월별지수!AL84)/키워드지표!$C84*100,"") -> 105.78329 | J84: =IFERROR(AVERAGE(월별지수!C84,월별지수!O84,월별지수!AA84)/키워드지표!$C84*100,"") -> 101.68564 | K84: =IFERROR(AVERAGE(월별지수!D84,월별지수!P84,월별지수!AB84)/키워드지표!$C84*100,"") -> 107.06666 | L84: =IFERROR(AVERAGE(월별지수!E84,월별지수!Q84,월별지수!AC84)/키워드지표!$C84*100,"") -> 85.939964 | M84: =IFERROR(AVERAGE(월별지수!F84,월별지수!R84,월별지수!AD84)/키워드지표!$C84*100,"") -> 92.747674

Sheet 키워드지표
A1: 키워드 | B1: 분류 | C1: 3년 평균 | D1: 1년차 2023.09–2024.08 | E1: 2년차 2024.09–2025.08 | F1: 3년차 2025.09–2026.08 | G1: 3년 변화 | H1: 변동계수 | I1: 스파이크 최대÷중앙 | J1: 피크월 | K1: 지역 | L1: 진료과
A2: 서울치과 | B2: 지역명+진료과 | C2: =AVERAGE(월별지수!C2:AL2) -> 86.903684 | D2: =AVERAGE(월별지수!C2:N2) -> 94.518559 | E2: =AVERAGE(월별지수!O2:Z2) -> 86.515731 | F2: =AVERAGE(월별지수!AA2:AL2) -> 79.676763 | G2: =IFERROR(F2/D2-1,"") -> -0.15702521 | H2: =IFERROR(STDEVP(월별지수!C2:AL2)/C2,"") -> 0.095594612 | I2: =IFERROR(MAX(월별지수!C2:AL2)/MEDIAN(월별지수!C2:AL2),"") -> 1.2018868 | J2: =INDEX(계절_월별!$B$1:$M$1,MATCH(MAX(계절_월별!B2:M2),계절_월별!B2:M2,0)) -> 1 | K2: 서울 | L2: 치과
A3: 부산치과 | B3: 지역명+진료과 | C3: =AVERAGE(월별지수!C3:AL3) -> 92.135686 | D3: =AVERAGE(월별지수!C3:N3) -> 99.450699 | E3: =AVERAGE(월별지수!O3:Z3) -> 96.943252 | F3: =AVERAGE(월별지수!AA3:AL3) -> 80.013108 | G3: =IFERROR(F3/D3-1,"") -> -0.19544951 | H3: =IFERROR(STDEVP(월별지수!C3:AL3)/C3,"") -> 0.45869777 | I3: =IFERROR(MAX(월별지수!C3:AL3)/MEDIAN(월별지수!C3:AL3),"") -> 2.9940066 | J3: =INDEX(계절_월별!$B$1:$M$1,MATCH(MAX(계절_월별!B3:M3),계절_월별!B3:M3,0)) -> 7 | K3: 부산 | L3: 치과
A4: 대구치과 | B4: 지역명+진료과 | C4: =AVERAGE(월별지수!C4:AL4) -> 122.2185 | D4: =AVERAGE(월별지수!C4:N4) -> 120.20786 | E4: =AVERAGE(월별지수!O4:Z4) -> 134.85657 | F4: =AVERAGE(월별지수!AA4:AL4) -> 111.59107 | G4: =IFERROR(F4/D4-1,"") -> -0.071682388 | H4: =IFERROR(STDEVP(월별지수!C4:AL4)/C4,"") -> 0.46315702 | I4: =IFERROR(MAX(월별지수!C4:AL4)/MEDIAN(월별지수!C4:AL4),"") -> 2.3690729 | J4: =INDEX(계절_월별!$B$1:$M$1,MATCH(MAX(계절_월별!B4:M4),계절_월별!B4:M4,0)) -> 3 | K4: 대구 | L4: 치과
A5: 인천치과 | B5: 지역명+진료과 | C5: =AVERAGE(월별지수!C5:AL5) -> 63.77789 | D5: =AVERAGE(월별지수!C5:N5) -> 65.003139 | E5: =AVERAGE(월별지수!O5:Z5) -> 68.441309 | F5: =AVERAGE(월별지수!AA5:AL5) -> 57.88922 | G5: =IFERROR(F5/D5-1,"") -> -0.10943963 | H5: =IFERROR(STDEVP(월별지수!C5:AL5)/C5,"") -> 0.25999271 | I5: =IFERROR(MAX(월별지수!C5:AL5)/MEDIAN(월별지수!C5:AL5),"") -> 1.7815306 | J5: =INDEX(계절_월별!$B$1:$M$1,MATCH(MAX(계절_월별!B5:M5),계절_월별!B5:M5,0)) -> 7 | K5: 인천 | L5: 치과
A6: 광주치과 | B6: 지역명+진료과 | C6: =AVERAGE(월별지수!C6:AL6) -> 67.569309 | D6: =AVERAGE(월별지수!C6:N6) -> 66.91264 | E6: =AVERAGE(월별지수!O6:Z6) -> 72.752372 | F6: =AVERAGE(월별지수!AA6:AL6) -> 63.042916 | G6: =IFERROR(F6/D6-1,"") -> -0.057832488 | H6: =IFERROR(STDEVP(월별지수!C6:AL6)/C6,"") -> 0.41238381 | I6: =IFERROR(MAX(월별지수!C6:AL6)/MEDIAN(월별지수!C6:AL6),"") -> 3.379232 | J6: =INDEX(계절_월별!$B$1:$M$1,MATCH(MAX(계절_월별!B6:M6),계절_월별!B6:M6,0)) -> 8 | K6: 광주 | L6: 치과
A7: 대전치과 | B7: 지역명+진료과 | C7: =AVERAGE(월별지수!C7:AL7) -> 104.81202 | D7: =AVERAGE(월별지수!C7:N7) -> 84.56263 | E7: =AVERAGE(월별지수!O7:Z7) -> 129.1156 | F7: =AVERAGE(월별지수!AA7:AL7) -> 100.75781 | G7: =IFERROR(F7/D7-1,"") -> 0.191517 | H7: =IFERROR(STDEVP(월별지수!C7:AL7)/C7,"") -> 0.26672475 | I7: =IFERROR(MAX(월별지수!C7:AL7)/MEDIAN(월별지수!C7:AL7),"") -> 1.7891199 | J7: =INDEX(계절_월별!$B$1:$M$1,MATCH(MAX(계절_월별!B7:M7),계절_월별!B7:M7,0)) -> 3 | K7: 대전 | L7: 치과
A8: 울산치과 | B8: 지역명+진료과 | C8: =AVERAGE(월별지수!C8:AL8) -> 90.561039 | D8: =AVERAGE(월별지수!C8:N8) -> 89.582854 | E8: =AVERAGE(월별지수!O8:Z8) -> 112.89373 | F8: =AVERAGE(월별지수!AA8:AL8) -> 69.206528 | G8: =IFERROR(F8/D8-1,"") -> -0.22745787 | H8: =IFERROR(STDEVP(월별지수!C8:AL8)/C8,"") -> 0.47696618 | I8: =IFERROR(MAX(월별지수!C8:AL8)/MEDIAN(월별지수!C8:AL8),"") -> 2.9971903 | J8: =INDEX(계절_월별!$B$1:$M$1,MATCH(MAX(계절_월별!B8:M8),계절_월별!B8:M8,0)) -> 3 | K8: 울산 | L8: 치과
A9: 서울한의원 | B9: 지역명+진료과 | C9: =AVERAGE(월별지수!C9:AL9) -> 27.239604 | D9: =AVERAGE(월별지수!C9:N9) -> 28.7137 | E9: =AVERAGE(월별지수!O9:Z9) -> 27.522263 | F9: =AVERAGE(월별지수!AA9:AL9) -> 25.482849 | G9: =IFERROR(F9/D9-1,"") -> -0.11251949 | H9: =IFERROR(STDEVP(월별지수!C9:AL9)/C9,"") -> 0.096111646 | I9: =IFERROR(MAX(월별지수!C9:AL9)/MEDIAN(월별지수!C9:AL9),"") -> 1.1893899 | J9: =INDEX(계절_월별!$B$1:$M$1,MATCH(MAX(계절_월별!B9:M9),계절_월별!B9:M9,0)) -> 8 | K9: 서울 | L9: 한의원
A10: 부산한의원 | B10: 지역명+진료과 | C10: =AVERAGE(월별지수!C10:AL10) -> 41.279994 | D10: =AVERAGE(월별지수!C10:N10) -> 57.961292 | E10: =AVERAGE(월별지수!O10:Z10) -> 28.839164 | F10: =AVERAGE(월별지수!AA10:AL10) -> 37.039525 | G10: =IFERROR(F10/D10-1,"") -> -0.36096102 | H10: =IFERROR(STDEVP(월별지수!C10:AL10)/C10,"") -> 0.54800431 | I10: =IFERROR(MAX(월별지수!C10:AL10)/MEDIAN(월별지수!C10:AL10),"") -> 3.5704364 | J10: =INDEX(계절_월별!$B$1:$M$1,MATCH(MAX(계절_월별!B10:M10),계절_월별!B10:M10,0)) -> 10 | K10: 부산 | L10: 한의원
A11: 대구한의원 | B11: 지역명+진료과 | C11: =AVERAGE(월별지수!C11:AL11) -> 43.274028 | D11: =AVERAGE(월별지수!C11:N11) -> 50.634718 | E11: =AVERAGE(월별지수!O11:Z11) -> 46.305857 | F11: =AVERAGE(월별지수!AA11:AL11) -> 32.881511 | G11: =IFERROR(F11/D11-1,"") -> -0.35061334 | H11: =IFERROR(STDEVP(월별지수!C11:AL11)/C11,"") -> 0.3328032 | I11: =IFERROR(MAX(월별지수!C11:AL11)/MEDIAN(월별지수!C11:AL11),"") -> 2.1596378 | J11: =INDEX(계절_월별!$B$1:$M$1,MATCH(MAX(계절_월별!B11:M11),계절_월별!B11:M11,0)) -> 4 | K11: 대구 | L11: 한의원
A12: 인천한의원 | B12: 지역명+진료과 | C12: =AVERAGE(월별지수!C12:AL12) -> 59.155994 | D12: =AVERAGE(월별지수!C12:N12) -> 89.200251 | E12: =AVERAGE(월별지수!O12:Z12) -> 46.283614 | F12: =AVERAGE(월별지수!AA12:AL12) -> 41.984117 | G12: =IFERROR(F12/D12-1,"") -> -0.52932737 | H12: =IFERROR(STDEVP(월별지수!C12:AL12)/C12,"") -> 0.55004933 | I12: =IFERROR(MAX(월별지수!C12:AL12)/MEDIAN(월별지수!C12:AL12),"") -> 4.3159919 | J12: =INDEX(계절_월별!$B$1:$M$1,MATCH(MAX(계절_월별!B12:M12),계절_월별!B12:M12,0)) -> 11 | K12: 인천 | L12: 한의원
A13: 광주한의원 | B13: 지역명+진료과 | C13: =AVERAGE(월별지수!C13:AL13) -> 22.579455 | D13: =AVERAGE(월별지수!C13:N13) -> 21.154892 | E13: =AVERAGE(월별지수!O13:Z13) -> 23.111553 | F13: =AVERAGE(월별지수!AA13:AL13) -> 23.47192 | G13: =IFERROR(F13/D13-1,"") -> 0.10952681 | H13: =IFERROR(STDEVP(월별지수!C13:AL13)/C13,"") -> 0.26074888 | I13: =IFERROR(MAX(월별지수!C13:AL13)/MEDIAN(월별지수!C13:AL13),"") -> 2.0758037 | J13: =INDEX(계절_월별!$B$1:$M$1,MATCH(MAX(계절_월별!B13:M13),계절_월별!B13:M13,0)) -> 9 | K13: 광주 | L13: 한의원
... A50: 울산성형외과 | B50: 지역명+진료과 | C50: =AVERAGE(월별지수!C50:AL50) -> 23.708605 | D50: =AVERAGE(월별지수!C50:N50) -> 28.312408 | E50: =AVERAGE(월별지수!O50:Z50) -> 22.487806 | F50: =AVERAGE(월별지수!AA50:AL50) -> 20.325602 | G50: =IFERROR(F50/D50-1,"") -> -0.28209559 | H50: =IFERROR(STDEVP(월별지수!C50:AL50)/C50,"") -> 0.20616758 | I50: =IFERROR(MAX(월별지수!C50:AL50)/MEDIAN(월별지수!C50:AL50),"") -> 1.5583317 | J50: =INDEX(계절_월별!$B$1:$M$1,MATCH(MAX(계절_월별!B50:M50),계절_월별!B50:M50,0)) -> 1 | K50: 울산 | L50: 성형외과
A51: 수원피부과 | B51: 중소도시 | C51: =AVERAGE(월별지수!C51:AL51) -> 194.18847 | D51: =AVERAGE(월별지수!C51:N51) -> 131.69423 | E51: =AVERAGE(월별지수!O51:Z51) -> 224.25883 | F51: =AVERAGE(월별지수!AA51:AL51) -> 226.61233 | G51: =IFERROR(F51/D51-1,"") -> 0.72074604 | H51: =IFERROR(STDEVP(월별지수!C51:AL51)/C51,"") -> 0.42731616 | I51: =IFERROR(MAX(월별지수!C51:AL51)/MEDIAN(월별지수!C51:AL51),"") -> 2.5561046 | J51: =INDEX(계절_월별!$B$1:$M$1,MATCH(MAX(계절_월별!B51:M51),계절_월별!B51:M51,0)) -> 7
A52: 창원피부과 | B52: 중소도시 | C52: =AVERAGE(월별지수!C52:AL52) -> 134.88238 | D52: =AVERAGE(월별지수!C52:N52) -> 127.64834 | E52: =AVERAGE(월별지수!O52:Z52) -> 143.92004 | F52: =AVERAGE(월별지수!AA52:AL52) -> 133.07876 | G52: =IFERROR(F52/D52-1,"") -> 0.042542093 | H52: =IFERROR(STDEVP(월별지수!C52:AL52)/C52,"") -> 0.31879192 | I52: =IFERROR(MAX(월별지수!C52:AL52)/MEDIAN(월별지수!C52:AL52),"") -> 2.0850011 | J52: =INDEX(계절_월별!$B$1:$M$1,MATCH(MAX(계절_월별!B52:M52),계절_월별!B52:M52,0)) -> 5
A53: 제주피부과 | B53: 중소도시 | C53: =AVERAGE(월별지수!C53:AL53) -> 50.478107 | D53: =AVERAGE(월별지수!C53:N53) -> 41.468031 | E53: =AVERAGE(월별지수!O53:Z53) -> 54.429695 | F53: =AVERAGE(월별지수!AA53:AL53) -> 55.536595 | G53: =IFERROR(F53/D53-1,"") -> 0.33926291 | H53: =IFERROR(STDEVP(월별지수!C53:AL53)/C53,"") -> 0.24337824 | I53: =IFERROR(MAX(월별지수!C53:AL53)/MEDIAN(월별지수!C53:AL53),"") -> 1.7206399 | J53: =INDEX(계절_월별!$B$1:$M$1,MATCH(MAX(계절_월별!B53:M53),계절_월별!B53:M53,0)) -> 3
A54: 수원치과 | B54: 중소도시 | C54: =AVERAGE(월별지수!C54:AL54) -> 155.84389 | D54: =AVERAGE(월별지수!C54:N54) -> 154.92503 | E54: =AVERAGE(월별지수!O54:Z54) -> 156.56938 | F54: =AVERAGE(월별지수!AA54:AL54) -> 156.03727 | G54: =IFERROR(F54/D54-1,"") -> 0.0071792255 | H54: =IFERROR(STDEVP(월별지수!C54:AL54)/C54,"") -> 0.36306413 | I54: =IFERROR(MAX(월별지수!C54:AL54)/MEDIAN(월별지수!C54:AL54),"") -> 1.8512555 | J54: =INDEX(계절_월별!$B$1:$M$1,MATCH(MAX(계절_월별!B54:M54),계절_월별!B54:M54,0)) -> 7
A55: 천안치과 | B55: 중소도시 | C55: =AVERAGE(월별지수!C55:AL55) -> 109.08363 | D55: =AVERAGE(월별지수!C55:N55) -> 75.954749 | E55: =AVERAGE(월별지수!O55:Z55) -> 163.54271 | F55: =AVERAGE(월별지수!AA55:AL55) -> 87.753438 | G55: =IFERROR(F55/D55-1,"") -> 0.1553384 | H55: =IFERROR(STDEVP(월별지수!C55:AL55)/C55,"") -> 0.78226218 | I55: =IFERROR(MAX(월별지수!C55:AL55)/MEDIAN(월별지수!C55:AL55),"") -> 5.2010741 | J55: =INDEX(계절_월별!$B$1:$M$1,MATCH(MAX(계절_월별!B55:M55),계절_월별!B55:M55,0)) -> 7
A56: 청주치과 | B56: 중소도시 | C56: =AVERAGE(월별지수!C56:AL56) -> 149.10399 | D56: =AVERAGE(월별지수!C56:N56) -> 91.826927 | E56: =AVERAGE(월별지수!O56:Z56) -> 239.03746 | F56: =AVERAGE(월별지수!AA56:AL56) -> 116.44758 | G56: =IFERROR(F56/D56-1,"") -> 0.26812015 | H56: =IFERROR(STDEVP(월별지수!C56:AL56)/C56,"") -> 0.6852742 | I56: =IFERROR(MAX(월별지수!C56:AL56)/MEDIAN(월별지수!C56:AL56),"") -> 4.9127218 | J56: =INDEX(계절_월별!$B$1:$M$1,MATCH(MAX(계절_월별!B56:M56),계절_월별!B56:M56,0)) -> 7
A57: 수원내과 | B57: 중소도시 | C57: =AVERAGE(월별지수!C57:AL57) -> 21.971723 | D57: =AVERAGE(월별지수!C57:N57) -> 22.150572 | E57: =AVERAGE(월별지수!O57:Z57) -> 21.429838 | F57: =AVERAGE(월별지수!AA57:AL57) -> 22.33476 | G57: =IFERROR(F57/D57-1,"") -> 0.008315284 | H57: =IFERROR(STDEVP(월별지수!C57:AL57)/C57,"") -> 0.23490387 | I57: =IFERROR(MAX(월별지수!C57:AL57)/MEDIAN(월별지수!C57:AL57),"") -> 1.9161945 | J57: =INDEX(계절_월별!$B$1:$M$1,MATCH(MAX(계절_월별!B57:M57),계절_월별!B57:M57,0)) -> 1
A58: 강남피부과 | B58: 상권 | C58: =AVERAGE(월별지수!C58:AL58) -> 215.21406 | D58: =AVERAGE(월별지수!C58:N58) -> 251.11377 | E58: =AVERAGE(월별지수!O58:Z58) -> 190.0524 | F58: =AVERAGE(월별지수!AA58:AL58) -> 204.476 | G58: =IFERROR(F58/D58-1,"") -> -0.18572365 | H58: =IFERROR(STDEVP(월별지수!C58:AL58)/C58,"") -> 0.21655509 | I58: =IFERROR(MAX(월별지수!C58:AL58)/MEDIAN(월별지수!C58:AL58),"") -> 1.6718719 | J58: =INDEX(계절_월별!$B$1:$M$1,MATCH(MAX(계절_월별!B58:M58),계절_월별!B58:M58,0)) -> 5
A59: 강남치과 | B59: 상권 | C59: =AVERAGE(월별지수!C59:AL59) -> 154.47035 | D59: =AVERAGE(월별지수!C59:N59) -> 99.760347 | E59: =AVERAGE(월별지수!O59:Z59) -> 219.58296 | F59: =AVERAGE(월별지수!AA59:AL59) -> 144.06774 | G59: =IFERROR(F59/D59-1,"") -> 0.44413837 | H59: =IFERROR(STDEVP(월별지수!C59:AL59)/C59,"") -> 0.71102803 | I59: =IFERROR(MAX(월별지수!C59:AL59)/MEDIAN(월별지수!C59:AL59),"") -> 4.7197484 | J59: =INDEX(계절_월별!$B$1:$M$1,MATCH(MAX(계절_월별!B59:M59),계절_월별!B59:M59,0)) -> 7
A60: 부평치과 | B60: 상권 | C60: =AVERAGE(월별지수!C60:AL60) -> 106.47623 | D60: =AVERAGE(월별지수!C60:N60) -> 116.16819 | E60: =AVERAGE(월별지수!O60:Z60) -> 116.50809 | F60: =AVERAGE(월별지수!AA60:AL60) -> 86.752424 | G60: =IFERROR(F60/D60-1,"") -> -0.25321703 | H60: =IFERROR(STDEVP(월별지수!C60:AL60)/C60,"") -> 0.51755478 | I60: =IFERROR(MAX(월별지수!C60:AL60)/MEDIAN(월별지수!C60:AL60),"") -> 2.7979901 | J60: =INDEX(계절_월별!$B$1:$M$1,MATCH(MAX(계절_월별!B60:M60),계절_월별!B60:M60,0)) -> 5
A61: 서면피부과 | B61: 상권 | C61: =AVERAGE(월별지수!C61:AL61) -> 219.44207 | D61: =AVERAGE(월별지수!C61:N61) -> 195.21055 | E61: =AVERAGE(월별지수!O61:Z61) -> 286.04182 | F61: =AVERAGE(월별지수!AA61:AL61) -> 177.07384 | G61: =IFERROR(F61/D61-1,"") -> -0.092908433 | H61: =IFERROR(STDEVP(월별지수!C61:AL61)/C61,"") -> 0.3203303 | I61: =IFERROR(MAX(월별지수!C61:AL61)/MEDIAN(월별지수!C61:AL61),"") -> 1.8449378 | J61: =INDEX(계절_월별!$B$1:$M$1,MATCH(MAX(계절_월별!B61:M61),계절_월별!B61:M61,0)) -> 2
A62: 피부과 | B62: 진료과단독 | C62: =AVERAGE(월별지수!C62:AL62) -> 5394.4498 | D62: =AVERAGE(월별지수!C62:N62) -> 5621.8705 | E62: =AVERAGE(월별지수!O62:Z62) -> 5419.9361 | F62: =AVERAGE(월별지수!AA62:AL62) -> 5141.5428 | G62: =IFERROR(F62/D62-1,"") -> -0.085439127 | H62: =IFERROR(STDEVP(월별지수!C62:AL62)/C62,"") -> 0.099855434 | I62: =IFERROR(MAX(월별지수!C62:AL62)/MEDIAN(월별지수!C62:AL62),"") -> 1.2128757 | J62: =INDEX(계절_월별!$B$1:$M$1,MATCH(MAX(계절_월별!B62:M62),계절_월별!B62:M62,0)) -> 8
... A84: 대구산부인과 | B84: 기타진료과(참고) | C84: =AVERAGE(월별지수!C84:AL84) -> 54.63435 | D84: =AVERAGE(월별지수!C84:N84) -> 55.832906 | E84: =AVERAGE(월별지수!O84:Z84) -> 56.290259 | F84: =AVERAGE(월별지수!AA84:AL84) -> 51.779885 | G84: =IFERROR(F84/D84-1,"") -> -0.072591984 | H84: =IFERROR(STDEVP(월별지수!C84:AL84)/C84,"") -> 0.093677044 | I84: =IFERROR(MAX(월별지수!C84:AL84)/MEDIAN(월별지수!C84:AL84),"") -> 1.2491895 | J84: =INDEX(계절_월별!$B$1:$M$1,MATCH(MAX(계절_월별!B84:M84),계절_월별!B84:M84,0)) -> 4

Sheet 요약_진료과
A1: 진료과 | B1: 3년 평균 | C1: 1년차 2023.09–2024.08 | D1: 2년차 2024.09–2025.08 | E1: 3년차 2025.09–2026.08 | F1: 3년 변화
A2: 치과 | B2: =SUMIFS(키워드지표!$C$2:$C$84,키워드지표!$L$2:$L$84,$A2,키워드지표!$B$2:$B$84,"지역명+진료과") -> 628 | C2: =SUMIFS(키워드지표!$D$2:$D$84,키워드지표!$L$2:$L$84,$A2,키워드지표!$B$2:$B$84,"지역명+진료과") -> 620.2 | D2: =SUMIFS(키워드지표!$E$2:$E$84,키워드지표!$L$2:$L$84,$A2,키워드지표!$B$2:$B$84,"지역명+진료과") -> 701.5 | E2: =SUMIFS(키워드지표!$F$2:$F$84,키워드지표!$L$2:$L$84,$A2,키워드지표!$B$2:$B$84,"지역명+진료과") -> 562.2 | F2: =IFERROR(E2/C2-1,"") -> -0.094
A3: 한의원 | B3: =SUMIFS(키워드지표!$C$2:$C$84,키워드지표!$L$2:$L$84,$A3,키워드지표!$B$2:$B$84,"지역명+진료과") -> 262 | C3: =SUMIFS(키워드지표!$D$2:$D$84,키워드지표!$L$2:$L$84,$A3,키워드지표!$B$2:$B$84,"지역명+진료과") -> 307 | D3: =SUMIFS(키워드지표!$E$2:$E$84,키워드지표!$L$2:$L$84,$A3,키워드지표!$B$2:$B$84,"지역명+진료과") -> 247.3 | E3: =SUMIFS(키워드지표!$F$2:$F$84,키워드지표!$L$2:$L$84,$A3,키워드지표!$B$2:$B$84,"지역명+진료과") -> 231.7 | F3: =IFERROR(E3/C3-1,"") -> -0.245
A4: 피부과 | B4: =SUMIFS(키워드지표!$C$2:$C$84,키워드지표!$L$2:$L$84,$A4,키워드지표!$B$2:$B$84,"지역명+진료과") -> 962.2 | C4: =SUMIFS(키워드지표!$D$2:$D$84,키워드지표!$L$2:$L$84,$A4,키워드지표!$B$2:$B$84,"지역명+진료과") -> 842.7 | D4: =SUMIFS(키워드지표!$E$2:$E$84,키워드지표!$L$2:$L$84,$A4,키워드지표!$B$2:$B$84,"지역명+진료과") -> 1075.8 | E4: =SUMIFS(키워드지표!$F$2:$F$84,키워드지표!$L$2:$L$84,$A4,키워드지표!$B$2:$B$84,"지역명+진료과") -> 968 | F4: =IFERROR(E4/C4-1,"") -> 0.149
A5: 정형외과 | B5: =SUMIFS(키워드지표!$C$2:$C$84,키워드지표!$L$2:$L$84,$A5,키워드지표!$B$2:$B$84,"지역명+진료과") -> 491.5 | C5: =SUMIFS(키워드지표!$D$2:$D$84,키워드지표!$L$2:$L$84,$A5,키워드지표!$B$2:$B$84,"지역명+진료과") -> 472.5 | D5: =SUMIFS(키워드지표!$E$2:$E$84,키워드지표!$L$2:$L$84,$A5,키워드지표!$B$2:$B$84,"지역명+진료과") -> 510.4 | E5: =SUMIFS(키워드지표!$F$2:$F$84,키워드지표!$L$2:$L$84,$A5,키워드지표!$B$2:$B$84,"지역명+진료과") -> 491.6 | F5: =IFERROR(E5/C5-1,"") -> 0.04
A6: 안과 | B6: =SUMIFS(키워드지표!$C$2:$C$84,키워드지표!$L$2:$L$84,$A6,키워드지표!$B$2:$B$84,"지역명+진료과") -> 578.9 | C6: =SUMIFS(키워드지표!$D$2:$D$84,키워드지표!$L$2:$L$84,$A6,키워드지표!$B$2:$B$84,"지역명+진료과") -> 592.1 | D6: =SUMIFS(키워드지표!$E$2:$E$84,키워드지표!$L$2:$L$84,$A6,키워드지표!$B$2:$B$84,"지역명+진료과") -> 587.2 | E6: =SUMIFS(키워드지표!$F$2:$F$84,키워드지표!$L$2:$L$84,$A6,키워드지표!$B$2:$B$84,"지역명+진료과") -> 557.5 | F6: =IFERROR(E6/C6-1,"") -> -0.058
A7: 내과 | B7: =SUMIFS(키워드지표!$C$2:$C$84,키워드지표!$L$2:$L$84,$A7,키워드지표!$B$2:$B$84,"지역명+진료과") -> 210 | C7: =SUMIFS(키워드지표!$D$2:$D$84,키워드지표!$L$2:$L$84,$A7,키워드지표!$B$2:$B$84,"지역명+진료과") -> 242.7 | D7: =SUMIFS(키워드지표!$E$2:$E$84,키워드지표!$L$2:$L$84,$A7,키워드지표!$B$2:$B$84,"지역명+진료과") -> 203.3 | E7: =SUMIFS(키워드지표!$F$2:$F$84,키워드지표!$L$2:$L$84,$A7,키워드지표!$B$2:$B$84,"지역명+진료과") -> 184 | F7: =IFERROR(E7/C7-1,"") -> -0.242
A8: 성형외과 | B8: =SUMIFS(키워드지표!$C$2:$C$84,키워드지표!$L$2:$L$84,$A8,키워드지표!$B$2:$B$84,"지역명+진료과") -> 401.9 | C8: =SUMIFS(키워드지표!$D$2:$D$84,키워드지표!$L$2:$L$84,$A8,키워드지표!$B$2:$B$84,"지역명+진료과") -> 342.9 | D8: =SUMIFS(키워드지표!$E$2:$E$84,키워드지표!$L$2:$L$84,$A8,키워드지표!$B$2:$B$84,"지역명+진료과") -> 447.1 | E8: =SUMIFS(키워드지표!$F$2:$F$84,키워드지표!$L$2:$L$84,$A8,키워드지표!$B$2:$B$84,"지역명+진료과") -> 415.6 | F8: =IFERROR(E8/C8-1,"") -> 0.212
A10: 7대 특·광역시 × 7개 진료과 49개 키워드만 합산한 값이다. 중소도시·상권·진료과단독 키워드는 제외.

Sheet 요약_지역
A1: 지역 | B1: 3년 평균 | C1: 1년차 2023.09–2024.08 | D1: 2년차 2024.09–2025.08 | E1: 3년차 2025.09–2026.08 | F1: 3년 변화
A2: 서울 | B2: =SUMIFS(키워드지표!$C$2:$C$84,키워드지표!$K$2:$K$84,$A2,키워드지표!$B$2:$B$84,"지역명+진료과") -> 713.5 | C2: =SUMIFS(키워드지표!$D$2:$D$84,키워드지표!$K$2:$K$84,$A2,키워드지표!$B$2:$B$84,"지역명+진료과") -> 772.4 | D2: =SUMIFS(키워드지표!$E$2:$E$84,키워드지표!$K$2:$K$84,$A2,키워드지표!$B$2:$B$84,"지역명+진료과") -> 720.7 | E2: =SUMIFS(키워드지표!$F$2:$F$84,키워드지표!$K$2:$K$84,$A2,키워드지표!$B$2:$B$84,"지역명+진료과") -> 647.3 | F2: =IFERROR(E2/C2-1,"") -> -0.162
A3: 부산 | B3: =SUMIFS(키워드지표!$C$2:$C$84,키워드지표!$K$2:$K$84,$A3,키워드지표!$B$2:$B$84,"지역명+진료과") -> 437.1 | C3: =SUMIFS(키워드지표!$D$2:$D$84,키워드지표!$K$2:$K$84,$A3,키워드지표!$B$2:$B$84,"지역명+진료과") -> 400.6 | D3: =SUMIFS(키워드지표!$E$2:$E$84,키워드지표!$K$2:$K$84,$A3,키워드지표!$B$2:$B$84,"지역명+진료과") -> 462.6 | E3: =SUMIFS(키워드지표!$F$2:$F$84,키워드지표!$K$2:$K$84,$A3,키워드지표!$B$2:$B$84,"지역명+진료과") -> 448 | F3: =IFERROR(E3/C3-1,"") -> 0.118
A4: 대구 | B4: =SUMIFS(키워드지표!$C$2:$C$84,키워드지표!$K$2:$K$84,$A4,키워드지표!$B$2:$B$84,"지역명+진료과") -> 599.9 | C4: =SUMIFS(키워드지표!$D$2:$D$84,키워드지표!$K$2:$K$84,$A4,키워드지표!$B$2:$B$84,"지역명+진료과") -> 554.1 | D4: =SUMIFS(키워드지표!$E$2:$E$84,키워드지표!$K$2:$K$84,$A4,키워드지표!$B$2:$B$84,"지역명+진료과") -> 657.1 | E4: =SUMIFS(키워드지표!$F$2:$F$84,키워드지표!$K$2:$K$84,$A4,키워드지표!$B$2:$B$84,"지역명+진료과") -> 588.5 | F4: =IFERROR(E4/C4-1,"") -> 0.062
A5: 인천 | B5: =SUMIFS(키워드지표!$C$2:$C$84,키워드지표!$K$2:$K$84,$A5,키워드지표!$B$2:$B$84,"지역명+진료과") -> 312.3 | C5: =SUMIFS(키워드지표!$D$2:$D$84,키워드지표!$K$2:$K$84,$A5,키워드지표!$B$2:$B$84,"지역명+진료과") -> 344.7 | D5: =SUMIFS(키워드지표!$E$2:$E$84,키워드지표!$K$2:$K$84,$A5,키워드지표!$B$2:$B$84,"지역명+진료과") -> 339.3 | E5: =SUMIFS(키워드지표!$F$2:$F$84,키워드지표!$K$2:$K$84,$A5,키워드지표!$B$2:$B$84,"지역명+진료과") -> 252.9 | F5: =IFERROR(E5/C5-1,"") -> -0.266
A6: 광주 | B6: =SUMIFS(키워드지표!$C$2:$C$84,키워드지표!$K$2:$K$84,$A6,키워드지표!$B$2:$B$84,"지역명+진료과") -> 483.6 | C6: =SUMIFS(키워드지표!$D$2:$D$84,키워드지표!$K$2:$K$84,$A6,키워드지표!$B$2:$B$84,"지역명+진료과") -> 467 | D6: =SUMIFS(키워드지표!$E$2:$E$84,키워드지표!$K$2:$K$84,$A6,키워드지표!$B$2:$B$84,"지역명+진료과") -> 477.4 | E6: =SUMIFS(키워드지표!$F$2:$F$84,키워드지표!$K$2:$K$84,$A6,키워드지표!$B$2:$B$84,"지역명+진료과") -> 506.3 | F6: =IFERROR(E6/C6-1,"") -> 0.084
A7: 대전 | B7: =SUMIFS(키워드지표!$C$2:$C$84,키워드지표!$K$2:$K$84,$A7,키워드지표!$B$2:$B$84,"지역명+진료과") -> 592.4 | C7: =SUMIFS(키워드지표!$D$2:$D$84,키워드지표!$K$2:$K$84,$A7,키워드지표!$B$2:$B$84,"지역명+진료과") -> 501.3 | D7: =SUMIFS(키워드지표!$E$2:$E$84,키워드지표!$K$2:$K$84,$A7,키워드지표!$B$2:$B$84,"지역명+진료과") -> 691.5 | E7: =SUMIFS(키워드지표!$F$2:$F$84,키워드지표!$K$2:$K$84,$A7,키워드지표!$B$2:$B$84,"지역명+진료과") -> 584.5 | F7: =IFERROR(E7/C7-1,"") -> 0.166
A8: 울산 | B8: =SUMIFS(키워드지표!$C$2:$C$84,키워드지표!$K$2:$K$84,$A8,키워드지표!$B$2:$B$84,"지역명+진료과") -> 395.8 | C8: =SUMIFS(키워드지표!$D$2:$D$84,키워드지표!$K$2:$K$84,$A8,키워드지표!$B$2:$B$84,"지역명+진료과") -> 380.1 | D8: =SUMIFS(키워드지표!$E$2:$E$84,키워드지표!$K$2:$K$84,$A8,키워드지표!$B$2:$B$84,"지역명+진료과") -> 424 | E8: =SUMIFS(키워드지표!$F$2:$F$84,키워드지표!$K$2:$K$84,$A8,키워드지표!$B$2:$B$84,"지역명+진료과") -> 383.2 | F8: =IFERROR(E8/C8-1,"") -> 0.008
A10: 7대 특·광역시 × 7개 진료과 49개 키워드만 합산한 값이다. 중소도시·상권·진료과단독 키워드는 제외.

Sheet 수요검증
A1: 「환자 검색 수요가 실제로 줄었나」 — 성격이 다른 네 묶음 비교
A2: 대조군(의료와 무관한 생활 키워드)을 넣은 이유: 네이버 검색 트래픽 자체가 줄고 있다면 모든 키워드가 같이 내려가 의료 수요 감소처럼 보이기 때문이다.
A4: 묶음 | B4: 키워드 | C4: 1년차 2023.09–2024.08 | D4: 2년차 2024.09–2025.08 | E4: 3년차 2025.09–2026.08 | F4: 3년 평균 | G4: 3년 변화
A5: 지역명+진료과 (병원 탐색) | B5: 49개 키워드 합산 | C5: =SUMIFS(키워드지표!$D$2:$D$84,키워드지표!$B$2:$B$84,"지역명+진료과") -> 3420.2 | D5: =SUMIFS(키워드지표!$E$2:$E$84,키워드지표!$B$2:$B$84,"지역명+진료과") -> 3772.7 | E5: =SUMIFS(키워드지표!$F$2:$F$84,키워드지표!$B$2:$B$84,"지역명+진료과") -> 3410.6 | F5: =SUMIFS(키워드지표!$C$2:$C$84,키워드지표!$B$2:$B$84,"지역명+진료과") -> 3534.5 | G5: =IFERROR(E5/C5-1,"") -> -0.003
A6: 진료과 단독 (전국 관심도) | B6: 피부과 | C6: =IFERROR(INDEX(키워드지표!$D$2:$D$84,MATCH($B6,키워드지표!$A$2:$A$84,0)),"") -> 5621.8705 | D6: =IFERROR(INDEX(키워드지표!$E$2:$E$84,MATCH($B6,키워드지표!$A$2:$A$84,0)),"") -> 5419.9361 | E6: =IFERROR(INDEX(키워드지표!$F$2:$F$84,MATCH($B6,키워드지표!$A$2:$A$84,0)),"") -> 5141.5428 | F6: =IFERROR(INDEX(키워드지표!$C$2:$C$84,MATCH($B6,키워드지표!$A$2:$A$84,0)),"") -> 5394.4498 | G6: =IFERROR(E6/C6-1,"") -> -0.085439127
B7: 치과 | C7: =IFERROR(INDEX(키워드지표!$D$2:$D$84,MATCH($B7,키워드지표!$A$2:$A$84,0)),"") -> 3057.9526 | D7: =IFERROR(INDEX(키워드지표!$E$2:$E$84,MATCH($B7,키워드지표!$A$2:$A$84,0)),"") -> 2888.5998 | E7: =IFERROR(INDEX(키워드지표!$F$2:$F$84,MATCH($B7,키워드지표!$A$2:$A$84,0)),"") -> 2736.7111 | F7: =IFERROR(INDEX(키워드지표!$C$2:$C$84,MATCH($B7,키워드지표!$A$2:$A$84,0)),"") -> 2894.4212 | G7: =IFERROR(E7/C7-1,"") -> -0.10505117
B8: 한의원 | C8: =IFERROR(INDEX(키워드지표!$D$2:$D$84,MATCH($B8,키워드지표!$A$2:$A$84,0)),"") -> 2078.7572 | D8: =IFERROR(INDEX(키워드지표!$E$2:$E$84,MATCH($B8,키워드지표!$A$2:$A$84,0)),"") -> 1942.6768 | E8: =IFERROR(INDEX(키워드지표!$F$2:$F$84,MATCH($B8,키워드지표!$A$2:$A$84,0)),"") -> 1725.1484 | F8: =IFERROR(INDEX(키워드지표!$C$2:$C$84,MATCH($B8,키워드지표!$A$2:$A$84,0)),"") -> 1915.5274 | G8: =IFERROR(E8/C8-1,"") -> -0.1701059
B9: 내과 | C9: =IFERROR(INDEX(키워드지표!$D$2:$D$84,MATCH($B9,키워드지표!$A$2:$A$84,0)),"") -> 5743.4251 | D9: =IFERROR(INDEX(키워드지표!$E$2:$E$84,MATCH($B9,키워드지표!$A$2:$A$84,0)),"") -> 5022.889 | E9: =IFERROR(INDEX(키워드지표!$F$2:$F$84,MATCH($B9,키워드지표!$A$2:$A$84,0)),"") -> 4542.6269 | F9: =IFERROR(INDEX(키워드지표!$C$2:$C$84,MATCH($B9,키워드지표!$A$2:$A$84,0)),"") -> 5102.9803 | G9: =IFERROR(E9/C9-1,"") -> -0.20907354
B10: 정형외과 | C10: =IFERROR(INDEX(키워드지표!$D$2:$D$84,MATCH($B10,키워드지표!$A$2:$A$84,0)),"") -> 5716.0922 | D10: =IFERROR(INDEX(키워드지표!$E$2:$E$84,MATCH($B10,키워드지표!$A$2:$A$84,0)),"") -> 5321.4175 | E10: =IFERROR(INDEX(키워드지표!$F$2:$F$84,MATCH($B10,키워드지표!$A$2:$A$84,0)),"") -> 4887.9723 | F10: =IFERROR(INDEX(키워드지표!$C$2:$C$84,MATCH($B10,키워드지표!$A$2:$A$84,0)),"") -> 5308.494 | G10: =IFERROR(E10/C10-1,"") -> -0.14487518
B11: 안과 | C11: =IFERROR(INDEX(키워드지표!$D$2:$D$84,MATCH($B11,키워드지표!$A$2:$A$84,0)),"") -> 3707.5591 | D11: =IFERROR(INDEX(키워드지표!$E$2:$E$84,MATCH($B11,키워드지표!$A$2:$A$84,0)),"") -> 3502.5663 | E11: =IFERROR(INDEX(키워드지표!$F$2:$F$84,MATCH($B11,키워드지표!$A$2:$A$84,0)),"") -> 3312.5917 | F11: =IFERROR(INDEX(키워드지표!$C$2:$C$84,MATCH($B11,키워드지표!$A$2:$A$84,0)),"") -> 3507.5723 | G11: =IFERROR(E11/C11-1,"") -> -0.10653031
B12: 성형외과 | C12: =IFERROR(INDEX(키워드지표!$D$2:$D$84,MATCH($B12,키워드지표!$A$2:$A$84,0)),"") -> 438.04413 | D12: =IFERROR(INDEX(키워드지표!$E$2:$E$84,MATCH($B12,키워드지표!$A$2:$A$84,0)),"") -> 392.06005 | E12: =IFERROR(INDEX(키워드지표!$F$2:$F$84,MATCH($B12,키워드지표!$A$2:$A$84,0)),"") -> 347.49895 | F12: =IFERROR(INDEX(키워드지표!$C$2:$C$84,MATCH($B12,키워드지표!$A$2:$A$84,0)),"") -> 392.53438 | G12: =IFERROR(E12/C12-1,"") -> -0.20670332
B13: 병원 | C13: =IFERROR(INDEX(키워드지표!$D$2:$D$84,MATCH($B13,키워드지표!$A$2:$A$84,0)),"") -> 2513.6716 | D13: =IFERROR(INDEX(키워드지표!$E$2:$E$84,MATCH($B13,키워드지표!$A$2:$A$84,0)),"") -> 2108.7988 | E13: =IFERROR(INDEX(키워드지표!$F$2:$F$84,MATCH($B13,키워드지표!$A$2:$A$84,0)),"") -> 1831.3792 | F13: =IFERROR(INDEX(키워드지표!$C$2:$C$84,MATCH($B13,키워드지표!$A$2:$A$84,0)),"") -> 2151.2832 | G13: =IFERROR(E13/C13-1,"") -> -0.27143258
A14: 시술·질환 (치료 의향) | B14: 임플란트 | C14: =IFERROR(INDEX(키워드지표!$D$2:$D$84,MATCH($B14,키워드지표!$A$2:$A$84,0)),"") -> 443.06341 | D14: =IFERROR(INDEX(키워드지표!$E$2:$E$84,MATCH($B14,키워드지표!$A$2:$A$84,0)),"") -> 397.4916 | E14: =IFERROR(INDEX(키워드지표!$F$2:$F$84,MATCH($B14,키워드지표!$A$2:$A$84,0)),"") -> 288.30734 | F14: =IFERROR(INDEX(키워드지표!$C$2:$C$84,MATCH($B14,키워드지표!$A$2:$A$84,0)),"") -> 376.28745 | G14: =IFERROR(E14/C14-1,"") -> -0.34928651
B15: 라식 | C15: =IFERROR(INDEX(키워드지표!$D$2:$D$84,MATCH($B15,키워드지표!$A$2:$A$84,0)),"") -> 199.77617 | D15: =IFERROR(INDEX(키워드지표!$E$2:$E$84,MATCH($B15,키워드지표!$A$2:$A$84,0)),"") -> 166.62768 | E15: =IFERROR(INDEX(키워드지표!$F$2:$F$84,MATCH($B15,키워드지표!$A$2:$A$84,0)),"") -> 114.5915 | F15: =IFERROR(INDEX(키워드지표!$C$2:$C$84,MATCH($B15,키워드지표!$A$2:$A$84,0)),"") -> 160.33178 | G15: =IFERROR(E15/C15-1,"") -> -0.42640059
B16: 도수치료 | C16: =IFERROR(INDEX(키워드지표!$D$2:$D$84,MATCH($B16,키워드지표!$A$2:$A$84,0)),"") -> 598.73689 | D16: =IFERROR(INDEX(키워드지표!$E$2:$E$84,MATCH($B16,키워드지표!$A$2:$A$84,0)),"") -> 544.06334 | E16: =IFERROR(INDEX(키워드지표!$F$2:$F$84,MATCH($B16,키워드지표!$A$2:$A$84,0)),"") -> 593.42304 | F16: =IFERROR(INDEX(키워드지표!$C$2:$C$84,MATCH($B16,키워드지표!$A$2:$A$84,0)),"") -> 578.74109 | G16: =IFERROR(E16/C16-1,"") -> -0.0088750991
B17: 여드름치료 | C17: =IFERROR(INDEX(키워드지표!$D$2:$D$84,MATCH($B17,키워드지표!$A$2:$A$84,0)),"") -> 35.787571 | D17: =IFERROR(INDEX(키워드지표!$E$2:$E$84,MATCH($B17,키워드지표!$A$2:$A$84,0)),"") -> 34.817666 | E17: =IFERROR(INDEX(키워드지표!$F$2:$F$84,MATCH($B17,키워드지표!$A$2:$A$84,0)),"") -> 26.660915 | F17: =IFERROR(INDEX(키워드지표!$C$2:$C$84,MATCH($B17,키워드지표!$A$2:$A$84,0)),"") -> 32.422051 | G17: =IFERROR(E17/C17-1,"") -> -0.25502306
A18: 대조군 — 의료와 무관 | B18: 날씨 | C18: =IFERROR(INDEX(키워드지표!$D$2:$D$84,MATCH($B18,키워드지표!$A$2:$A$84,0)),"") -> 448466.6 | D18: =IFERROR(INDEX(키워드지표!$E$2:$E$84,MATCH($B18,키워드지표!$A$2:$A$84,0)),"") -> 435855.84 | E18: =IFERROR(INDEX(키워드지표!$F$2:$F$84,MATCH($B18,키워드지표!$A$2:$A$84,0)),"") -> 422933.86 | F18: =IFERROR(INDEX(키워드지표!$C$2:$C$84,MATCH($B18,키워드지표!$A$2:$A$84,0)),"") -> 435752.1 | G18: =IFERROR(E18/C18-1,"") -> -0.056933429
B19: 지하철 | C19: =IFERROR(INDEX(키워드지표!$D$2:$D$84,MATCH($B19,키워드지표!$A$2:$A$84,0)),"") -> 3560.285 | D19: =IFERROR(INDEX(키워드지표!$E$2:$E$84,MATCH($B19,키워드지표!$A$2:$A$84,0)),"") -> 3189.9563 | E19: =IFERROR(INDEX(키워드지표!$F$2:$F$84,MATCH($B19,키워드지표!$A$2:$A$84,0)),"") -> 2619.7068 | F19: =IFERROR(INDEX(키워드지표!$C$2:$C$84,MATCH($B19,키워드지표!$A$2:$A$84,0)),"") -> 3123.316 | G19: =IFERROR(E19/C19-1,"") -> -0.26418621
B20: 환율 | C20: =IFERROR(INDEX(키워드지표!$D$2:$D$84,MATCH($B20,키워드지표!$A$2:$A$84,0)),"") -> 124110.31 | D20: =IFERROR(INDEX(키워드지표!$E$2:$E$84,MATCH($B20,키워드지표!$A$2:$A$84,0)),"") -> 162777.16 | E20: =IFERROR(INDEX(키워드지표!$F$2:$F$84,MATCH($B20,키워드지표!$A$2:$A$84,0)),"") -> 220336.5 | F20: =IFERROR(INDEX(키워드지표!$C$2:$C$84,MATCH($B20,키워드지표!$A$2:$A$84,0)),"") -> 169074.66 | G20: =IFERROR(E20/C20-1,"") -> 0.77532792
B21: 로또 | C21: =IFERROR(INDEX(키워드지표!$D$2:$D$84,MATCH($B21,키워드지표!$A$2:$A$84,0)),"") -> 74365.464 | D21: =IFERROR(INDEX(키워드지표!$E$2:$E$84,MATCH($B21,키워드지표!$A$2:$A$84,0)),"") -> 149501.04 | E21: =IFERROR(INDEX(키워드지표!$F$2:$F$84,MATCH($B21,키워드지표!$A$2:$A$84,0)),"") -> 166396.99 | F21: =IFERROR(INDEX(키워드지표!$C$2:$C$84,MATCH($B21,키워드지표!$A$2:$A$84,0)),"") -> 130087.83 | G21: =IFERROR(E21/C21-1,"") -> 1.2375573
A24: 읽는 법
A25: ① 대조군은 일률적으로 내려가지 않았다(로또·환율 큰 폭 상승). 따라서 네이버 지수 전반의 하향 편향은 없고, 의료 키워드 하락은 실제 신호다.
A26: ② 시장 축소의 증거는 시술 키워드에 있다. 라식·임플란트는 지도앱으로 대체되지 않으므로 치료 의향 자체가 빠졌다고 읽는 편이 자연스럽다.
A27: ③ 그런데 지역명+진료과 총량은 거의 그대로다. 줄어든 게 아니라 자리가 바뀌었다 — 내과·한의원에서 피부과·성형외과로, 수도권에서 지방으로.
A28: ④ 대조군 안에서도 지하철·날씨가 내려간 것은 「검색창 → 앱」 이동 흔적이다. 「병원」 단독 검색의 낙폭이 이와 비슷한 점은 병원 찾기가 지도·플레이스로 옮겨갔을 가능성을 시사한다.
A30: 주의 — 도수치료는 실손보험 제도 이슈로 2026년 6월 지수가 100까지 튄 예외 계열이라 추세로 읽으면 안 된다. 시술 키워드 4개는 진료과 전체를 대표하지 않는다.
A31: 묶음끼리 절대 크기는 비교하지 말 것. 같은 행의 연차별 변화만 볼 것.

Sheet TOP3
A1: 진료과별 대표 키워드 상위 3개 (7대 특·광역시 안에서 · 도시 후보 수가 같아 진료과끼리 공정 비교)
A3: 진료과 | B3: 순위 | C3: 키워드 | D3: 1년차 2023.09–2024.08 | E3: 2년차 2024.09–2025.08 | F3: 3년차 2025.09–2026.08 | G3: 3년 평균 | H3: 3년 변화 | I3: 피크월
A4: 치과 | B4: 1 | C4: 대구치과 | D4: =IFERROR(INDEX(키워드지표!$D$2:$D$84,MATCH($C4,키워드지표!$A$2:$A$84,0)),"") -> 120.2 | E4: =IFERROR(INDEX(키워드지표!$E$2:$E$84,MATCH($C4,키워드지표!$A$2:$A$84,0)),"") -> 134.9 | F4: =IFERROR(INDEX(키워드지표!$F$2:$F$84,MATCH($C4,키워드지표!$A$2:$A$84,0)),"") -> 111.6 | G4: =IFERROR(INDEX(키워드지표!$C$2:$C$84,MATCH($C4,키워드지표!$A$2:$A$84,0)),"") -> 122.2 | H4: =IFERROR(F4/D4-1,"") -> -0.072 | I4: =IFERROR(INDEX(키워드지표!$J$2:$J$84,MATCH($C4,키워드지표!$A$2:$A$84,0)),"") -> 3
B5: 2 | C5: 대전치과 | D5: =IFERROR(INDEX(키워드지표!$D$2:$D$84,MATCH($C5,키워드지표!$A$2:$A$84,0)),"") -> 84.6 | E5: =IFERROR(INDEX(키워드지표!$E$2:$E$84,MATCH($C5,키워드지표!$A$2:$A$84,0)),"") -> 129.1 | F5: =IFERROR(INDEX(키워드지표!$F$2:$F$84,MATCH($C5,키워드지표!$A$2:$A$84,0)),"") -> 100.8 | G5: =IFERROR(INDEX(키워드지표!$C$2:$C$84,MATCH($C5,키워드지표!$A$2:$A$84,0)),"") -> 104.8 | H5: =IFERROR(F5/D5-1,"") -> 0.192 | I5: =IFERROR(INDEX(키워드지표!$J$2:$J$84,MATCH($C5,키워드지표!$A$2:$A$84,0)),"") -> 3
B6: 3 | C6: 부산치과 | D6: =IFERROR(INDEX(키워드지표!$D$2:$D$84,MATCH($C6,키워드지표!$A$2:$A$84,0)),"") -> 99.5 | E6: =IFERROR(INDEX(키워드지표!$E$2:$E$84,MATCH($C6,키워드지표!$A$2:$A$84,0)),"") -> 96.9 | F6: =IFERROR(INDEX(키워드지표!$F$2:$F$84,MATCH($C6,키워드지표!$A$2:$A$84,0)),"") -> 80 | G6: =IFERROR(INDEX(키워드지표!$C$2:$C$84,MATCH($C6,키워드지표!$A$2:$A$84,0)),"") -> 92.1 | H6: =IFERROR(F6/D6-1,"") -> -0.195 | I6: =IFERROR(INDEX(키워드지표!$J$2:$J$84,MATCH($C6,키워드지표!$A$2:$A$84,0)),"") -> 7
C7: 7대 도시 밖 참고 — 수원치과 155.8 · 강남치과 154.5 · 청주치과 149.1 · 천안치과 109.1 · 부평치과 106.5
A8: 한의원 | B8: 1 | C8: 인천한의원 | D8: =IFERROR(INDEX(키워드지표!$D$2:$D$84,MATCH($C8,키워드지표!$A$2:$A$84,0)),"") -> 89.2 | E8: =IFERROR(INDEX(키워드지표!$E$2:$E$84,MATCH($C8,키워드지표!$A$2:$A$84,0)),"") -> 46.3 | F8: =IFERROR(INDEX(키워드지표!$F$2:$F$84,MATCH($C8,키워드지표!$A$2:$A$84,0)),"") -> 42 | G8: =IFERROR(INDEX(키워드지표!$C$2:$C$84,MATCH($C8,키워드지표!$A$2:$A$84,0)),"") -> 59.2 | H8: =IFERROR(F8/D8-1,"") -> -0.529 | I8: =IFERROR(INDEX(키워드지표!$J$2:$J$84,MATCH($C8,키워드지표!$A$2:$A$84,0)),"") -> 11
B9: 2 | C9: 대구한의원 | D9: =IFERROR(INDEX(키워드지표!$D$2:$D$84,MATCH($C9,키워드지표!$A$2:$A$84,0)),"") -> 50.6 | E9: =IFERROR(INDEX(키워드지표!$E$2:$E$84,MATCH($C9,키워드지표!$A$2:$A$84,0)),"") -> 46.3 | F9: =IFERROR(INDEX(키워드지표!$F$2:$F$84,MATCH($C9,키워드지표!$A$2:$A$84,0)),"") -> 32.9 | G9: =IFERROR(INDEX(키워드지표!$C$2:$C$84,MATCH($C9,키워드지표!$A$2:$A$84,0)),"") -> 43.3 | H9: =IFERROR(F9/D9-1,"") -> -0.351 | I9: =IFERROR(INDEX(키워드지표!$J$2:$J$84,MATCH($C9,키워드지표!$A$2:$A$84,0)),"") -> 4
B10: 3 | C10: 부산한의원 | D10: =IFERROR(INDEX(키워드지표!$D$2:$D$84,MATCH($C10,키워드지표!$A$2:$A$84,0)),"") -> 58 | E10: =IFERROR(INDEX(키워드지표!$E$2:$E$84,MATCH($C10,키워드지표!$A$2:$A$84,0)),"") -> 28.8 | F10: =IFERROR(INDEX(키워드지표!$F$2:$F$84,MATCH($C10,키워드지표!$A$2:$A$84,0)),"") -> 37 | G10: =IFERROR(INDEX(키워드지표!$C$2:$C$84,MATCH($C10,키워드지표!$A$2:$A$84,0)),"") -> 41.3 | H10: =IFERROR(F10/D10-1,"") -> -0.361 | I10: =IFERROR(INDEX(키워드지표!$J$2:$J$84,MATCH($C10,키워드지표!$A$2:$A$84,0)),"") -> 10
A11: 피부과 | B11: 1 | C11: 대전피부과 | D11: =IFERROR(INDEX(키워드지표!$D$2:$D$84,MATCH($C11,키워드지표!$A$2:$A$84,0)),"") -> 174.5 | E11: =IFERROR(INDEX(키워드지표!$E$2:$E$84,MATCH($C11,키워드지표!$A$2:$A$84,0)),"") -> 300.9 | F11: =IFERROR(INDEX(키워드지표!$F$2:$F$84,MATCH($C11,키워드지표!$A$2:$A$84,0)),"") -> 226.1 | G11: =IFERROR(INDEX(키워드지표!$C$2:$C$84,MATCH($C11,키워드지표!$A$2:$A$84,0)),"") -> 233.8 | H11: =IFERROR(F11/D11-1,"") -> 0.296 | I11: =IFERROR(INDEX(키워드지표!$J$2:$J$84,MATCH($C11,키워드지표!$A$2:$A$84,0)),"") -> 4
B12: 2 | C12: 대구피부과 | D12: =IFERROR(INDEX(키워드지표!$D$2:$D$84,MATCH($C12,키워드지표!$A$2:$A$84,0)),"") -> 146 | E12: =IFERROR(INDEX(키워드지표!$E$2:$E$84,MATCH($C12,키워드지표!$A$2:$A$84,0)),"") -> 172.6 | F12: =IFERROR(INDEX(키워드지표!$F$2:$F$84,MATCH($C12,키워드지표!$A$2:$A$84,0)),"") -> 164.5 | G12: =IFERROR(INDEX(키워드지표!$C$2:$C$84,MATCH($C12,키워드지표!$A$2:$A$84,0)),"") -> 161 | H12: =IFERROR(F12/D12-1,"") -> 0.126 | I12: =IFERROR(INDEX(키워드지표!$J$2:$J$84,MATCH($C12,키워드지표!$A$2:$A$84,0)),"") -> 4
B13: 3 | C13: 광주피부과 | D13: =IFERROR(INDEX(키워드지표!$D$2:$D$84,MATCH($C13,키워드지표!$A$2:$A$84,0)),"") -> 126.8 | E13: =IFERROR(INDEX(키워드지표!$E$2:$E$84,MATCH($C13,키워드지표!$A$2:$A$84,0)),"") -> 131.1 | F13: =IFERROR(INDEX(키워드지표!$F$2:$F$84,MATCH($C13,키워드지표!$A$2:$A$84,0)),"") -> 161.1 | G13: =IFERROR(INDEX(키워드지표!$C$2:$C$84,MATCH($C13,키워드지표!$A$2:$A$84,0)),"") -> 139.7 | H13: =IFERROR(F13/D13-1,"") -> 0.271 | I13: =IFERROR(INDEX(키워드지표!$J$2:$J$84,MATCH($C13,키워드지표!$A$2:$A$84,0)),"") -> 2
C14: 7대 도시 밖 참고 — 서면피부과 219.4 · 강남피부과 215.2 · 수원피부과 194.2
A15: 정형외과 | B15: 1 | C15: 서울정형외과 | D15: =IFERROR(INDEX(키워드지표!$D$2:$D$84,MATCH($C15,키워드지표!$A$2:$A$84,0)),"") -> 186.1 | E15: =IFERROR(INDEX(키워드지표!$E$2:$E$84,MATCH($C15,키워드지표!$A$2:$A$84,0)),"") -> 179.8 | F15: =IFERROR(INDEX(키워드지표!$F$2:$F$84,MATCH($C15,키워드지표!$A$2:$A$84,0)),"") -> 164.5 | G15: =IFERROR(INDEX(키워드지표!$C$2:$C$84,MATCH($C15,키워드지표!$A$2:$A$84,0)),"") -> 176.8 | H15: =IFERROR(F15/D15-1,"") -> -0.116 | I15: =IFERROR(INDEX(키워드지표!$J$2:$J$84,MATCH($C15,키워드지표!$A$2:$A$84,0)),"") -> 5
B16: 2 | C16: 대전정형외과 | D16: =IFERROR(INDEX(키워드지표!$D$2:$D$84,MATCH($C16,키워드지표!$A$2:$A$84,0)),"") -> 67.6 | E16: =IFERROR(INDEX(키워드지표!$E$2:$E$84,MATCH($C16,키워드지표!$A$2:$A$84,0)),"") -> 80.1 | F16: =IFERROR(INDEX(키워드지표!$F$2:$F$84,MATCH($C16,키워드지표!$A$2:$A$84,0)),"") -> 81.3 | G16: =IFERROR(INDEX(키워드지표!$C$2:$C$84,MATCH($C16,키워드지표!$A$2:$A$84,0)),"") -> 76.4 | H16: =IFERROR(F16/D16-1,"") -> 0.203 | I16: =IFERROR(INDEX(키워드지표!$J$2:$J$84,MATCH($C16,키워드지표!$A$2:$A$84,0)),"") -> 4
B17: 3 | C17: 대구정형외과 | D17: =IFERROR(INDEX(키워드지표!$D$2:$D$84,MATCH($C17,키워드지표!$A$2:$A$84,0)),"") -> 51.3 | E17: =IFERROR(INDEX(키워드지표!$E$2:$E$84,MATCH($C17,키워드지표!$A$2:$A$84,0)),"") -> 76.6 | F17: =IFERROR(INDEX(키워드지표!$F$2:$F$84,MATCH($C17,키워드지표!$A$2:$A$84,0)),"") -> 67.6 | G17: =IFERROR(INDEX(키워드지표!$C$2:$C$84,MATCH($C17,키워드지표!$A$2:$A$84,0)),"") -> 65.2 | H17: =IFERROR(F17/D17-1,"") -> 0.316 | I17: =IFERROR(INDEX(키워드지표!$J$2:$J$84,MATCH($C17,키워드지표!$A$2:$A$84,0)),"") -> 6
A18: 안과 | B18: 1 | C18: 서울안과 | D18: =IFERROR(INDEX(키워드지표!$D$2:$D$84,MATCH($C18,키워드지표!$A$2:$A$84,0)),"") -> 231.1 | E18: =IFERROR(INDEX(키워드지표!$E$2:$E$84,MATCH($C18,키워드지표!$A$2:$A$84,0)),"") -> 215.8 | F18: =IFERROR(INDEX(키워드지표!$F$2:$F$84,MATCH($C18,키워드지표!$A$2:$A$84,0)),"") -> 196.6 | G18: =IFERROR(INDEX(키워드지표!$C$2:$C$84,MATCH($C18,키워드지표!$A$2:$A$84,0)),"") -> 214.5 | H18: =IFERROR(F18/D18-1,"") -> -0.15 | I18: =IFERROR(INDEX(키워드지표!$J$2:$J$84,MATCH($C18,키워드지표!$A$2:$A$84,0)),"") -> 8
B19: 2 | C19: 광주안과 | D19: =IFERROR(INDEX(키워드지표!$D$2:$D$84,MATCH($C19,키워드지표!$A$2:$A$84,0)),"") -> 129.6 | E19: =IFERROR(INDEX(키워드지표!$E$2:$E$84,MATCH($C19,키워드지표!$A$2:$A$84,0)),"") -> 134.5 | F19: =IFERROR(INDEX(키워드지표!$F$2:$F$84,MATCH($C19,키워드지표!$A$2:$A$84,0)),"") -> 132.1 | G19: =IFERROR(INDEX(키워드지표!$C$2:$C$84,MATCH($C19,키워드지표!$A$2:$A$84,0)),"") -> 132.1 | H19: =IFERROR(F19/D19-1,"") -> 0.019 | I19: =IFERROR(INDEX(키워드지표!$J$2:$J$84,MATCH($C19,키워드지표!$A$2:$A$84,0)),"") -> 1
B20: 3 | C20: 대구안과 | D20: =IFERROR(INDEX(키워드지표!$D$2:$D$84,MATCH($C20,키워드지표!$A$2:$A$84,0)),"") -> 68 | E20: =IFERROR(INDEX(키워드지표!$E$2:$E$84,MATCH($C20,키워드지표!$A$2:$A$84,0)),"") -> 66.8 | F20: =IFERROR(INDEX(키워드지표!$F$2:$F$84,MATCH($C20,키워드지표!$A$2:$A$84,0)),"") -> 64.7 | G20: =IFERROR(INDEX(키워드지표!$C$2:$C$84,MATCH($C20,키워드지표!$A$2:$A$84,0)),"") -> 66.5 | H20: =IFERROR(F20/D20-1,"") -> -0.049 | I20: =IFERROR(INDEX(키워드지표!$J$2:$J$84,MATCH($C20,키워드지표!$A$2:$A$84,0)),"") -> 8
A21: 내과 | B21: 1 | C21: 서울내과 | D21: =IFERROR(INDEX(키워드지표!$D$2:$D$84,MATCH($C21,키워드지표!$A$2:$A$84,0)),"") -> 88.7 | E21: =IFERROR(INDEX(키워드지표!$E$2:$E$84,MATCH($C21,키워드지표!$A$2:$A$84,0)),"") -> 75 | F21: =IFERROR(INDEX(키워드지표!$F$2:$F$84,MATCH($C21,키워드지표!$A$2:$A$84,0)),"") -> 65.5 | G21: =IFERROR(INDEX(키워드지표!$C$2:$C$84,MATCH($C21,키워드지표!$A$2:$A$84,0)),"") -> 76.4 | H21: =IFERROR(F21/D21-1,"") -> -0.261 | I21: =IFERROR(INDEX(키워드지표!$J$2:$J$84,MATCH($C21,키워드지표!$A$2:$A$84,0)),"") -> 12
B22: 2 | C22: 대전내과 | D22: =IFERROR(INDEX(키워드지표!$D$2:$D$84,MATCH($C22,키워드지표!$A$2:$A$84,0)),"") -> 38.6 | E22: =IFERROR(INDEX(키워드지표!$E$2:$E$84,MATCH($C22,키워드지표!$A$2:$A$84,0)),"") -> 32.3 | F22: =IFERROR(INDEX(키워드지표!$F$2:$F$84,MATCH($C22,키워드지표!$A$2:$A$84,0)),"") -> 28.2 | G22: =IFERROR(INDEX(키워드지표!$C$2:$C$84,MATCH($C22,키워드지표!$A$2:$A$84,0)),"") -> 33 | H22: =IFERROR(F22/D22-1,"") -> -0.27 | I22: =IFERROR(INDEX(키워드지표!$J$2:$J$84,MATCH($C22,키워드지표!$A$2:$A$84,0)),"") -> 10
B23: 3 | C23: 울산내과 | D23: =IFERROR(INDEX(키워드지표!$D$2:$D$84,MATCH($C23,키워드지표!$A$2:$A$84,0)),"") -> 33.9 | E23: =IFERROR(INDEX(키워드지표!$E$2:$E$84,MATCH($C23,키워드지표!$A$2:$A$84,0)),"") -> 26.5 | F23: =IFERROR(INDEX(키워드지표!$F$2:$F$84,MATCH($C23,키워드지표!$A$2:$A$84,0)),"") -> 23.1 | G23: =IFERROR(INDEX(키워드지표!$C$2:$C$84,MATCH($C23,키워드지표!$A$2:$A$84,0)),"") -> 27.8 | H23: =IFERROR(F23/D23-1,"") -> -0.319 | I23: =IFERROR(INDEX(키워드지표!$J$2:$J$84,MATCH($C23,키워드지표!$A$2:$A$84,0)),"") -> 1
A24: 성형외과 | B24: 1 | C24: 대구성형외과 | D24: =IFERROR(INDEX(키워드지표!$D$2:$D$84,MATCH($C24,키워드지표!$A$2:$A$84,0)),"") -> 92.1 | E24: =IFERROR(INDEX(키워드지표!$E$2:$E$84,MATCH($C24,키워드지표!$A$2:$A$84,0)),"") -> 137.9 | F24: =IFERROR(INDEX(키워드지표!$F$2:$F$84,MATCH($C24,키워드지표!$A$2:$A$84,0)),"") -> 126.4 | G24: =IFERROR(INDEX(키워드지표!$C$2:$C$84,MATCH($C24,키워드지표!$A$2:$A$84,0)),"") -> 118.8 | H24: =IFERROR(F24/D24-1,"") -> 0.373 | I24: =IFERROR(INDEX(키워드지표!$J$2:$J$84,MATCH($C24,키워드지표!$A$2:$A$84,0)),"") -> 3
B25: 2 | C25: 부산성형외과 | D25: =IFERROR(INDEX(키워드지표!$D$2:$D$84,MATCH($C25,키워드지표!$A$2:$A$84,0)),"") -> 53 | E25: =IFERROR(INDEX(키워드지표!$E$2:$E$84,MATCH($C25,키워드지표!$A$2:$A$84,0)),"") -> 83.6 | F25: =IFERROR(INDEX(키워드지표!$F$2:$F$84,MATCH($C25,키워드지표!$A$2:$A$84,0)),"") -> 96.6 | G25: =IFERROR(INDEX(키워드지표!$C$2:$C$84,MATCH($C25,키워드지표!$A$2:$A$84,0)),"") -> 77.7 | H25: =IFERROR(F25/D25-1,"") -> 0.822 | I25: =IFERROR(INDEX(키워드지표!$J$2:$J$84,MATCH($C25,키워드지표!$A$2:$A$84,0)),"") -> 7
B26: 3 | C26: 광주성형외과 | D26: =IFERROR(INDEX(키워드지표!$D$2:$D$84,MATCH($C26,키워드지표!$A$2:$A$84,0)),"") -> 56 | E26: =IFERROR(INDEX(키워드지표!$E$2:$E$84,MATCH($C26,키워드지표!$A$2:$A$84,0)),"") -> 49.3 | F26: =IFERROR(INDEX(키워드지표!$F$2:$F$84,MATCH($C26,키워드지표!$A$2:$A$84,0)),"") -> 63.8 | G26: =IFERROR(INDEX(키워드지표!$C$2:$C$84,MATCH($C26,키워드지표!$A$2:$A$84,0)),"") -> 56.4 | H26: =IFERROR(F26/D26-1,"") -> 0.139 | I26: =IFERROR(INDEX(키워드지표!$J$2:$J$84,MATCH($C26,키워드지표!$A$2:$A$84,0)),"") -> 12
A28: 순위는 7대 도시 안에서만 매겼다. 중소도시·상권 키워드는 수집 범위가 진료과마다 달라 순위에 넣지 않고 참고로만 적었다.

Sheet 매트릭스
A1: ① 수요 규모 — 3년 평균 지수 (서울피부과 36개월 평균 = 100)
A2: 진료과 | B2: 서울 | C2: 부산 | D2: 대구 | E2: 인천 | F2: 광주 | G2: 대전 | H2: 울산 | I2: 합계
A3: 치과 | B3: =IFERROR(INDEX(키워드지표!$C$2:$C$84,MATCH(B$2&$A3,키워드지표!$A$2:$A$84,0)),"") -> 86.9 | C3: =IFERROR(INDEX(키워드지표!$C$2:$C$84,MATCH(C$2&$A3,키워드지표!$A$2:$A$84,0)),"") -> 92.1 | D3: =IFERROR(INDEX(키워드지표!$C$2:$C$84,MATCH(D$2&$A3,키워드지표!$A$2:$A$84,0)),"") -> 122.2 | E3: =IFERROR(INDEX(키워드지표!$C$2:$C$84,MATCH(E$2&$A3,키워드지표!$A$2:$A$84,0)),"") -> 63.8 | F3: =IFERROR(INDEX(키워드지표!$C$2:$C$84,MATCH(F$2&$A3,키워드지표!$A$2:$A$84,0)),"") -> 67.6 | G3: =IFERROR(INDEX(키워드지표!$C$2:$C$84,MATCH(G$2&$A3,키워드지표!$A$2:$A$84,0)),"") -> 104.8 | H3: =IFERROR(INDEX(키워드지표!$C$2:$C$84,MATCH(H$2&$A3,키워드지표!$A$2:$A$84,0)),"") -> 90.6 | I3: =SUM(B3:H3) -> 628
A4: 한의원 | B4: =IFERROR(INDEX(키워드지표!$C$2:$C$84,MATCH(B$2&$A4,키워드지표!$A$2:$A$84,0)),"") -> 27.2 | C4: =IFERROR(INDEX(키워드지표!$C$2:$C$84,MATCH(C$2&$A4,키워드지표!$A$2:$A$84,0)),"") -> 41.3 | D4: =IFERROR(INDEX(키워드지표!$C$2:$C$84,MATCH(D$2&$A4,키워드지표!$A$2:$A$84,0)),"") -> 43.3 | E4: =IFERROR(INDEX(키워드지표!$C$2:$C$84,MATCH(E$2&$A4,키워드지표!$A$2:$A$84,0)),"") -> 59.2 | F4: =IFERROR(INDEX(키워드지표!$C$2:$C$84,MATCH(F$2&$A4,키워드지표!$A$2:$A$84,0)),"") -> 22.6 | G4: =IFERROR(INDEX(키워드지표!$C$2:$C$84,MATCH(G$2&$A4,키워드지표!$A$2:$A$84,0)),"") -> 39 | H4: =IFERROR(INDEX(키워드지표!$C$2:$C$84,MATCH(H$2&$A4,키워드지표!$A$2:$A$84,0)),"") -> 29.5 | I4: =SUM(B4:H4) -> 262
A5: 피부과 | B5: =IFERROR(INDEX(키워드지표!$C$2:$C$84,MATCH(B$2&$A5,키워드지표!$A$2:$A$84,0)),"") -> 100 | C5: =IFERROR(INDEX(키워드지표!$C$2:$C$84,MATCH(C$2&$A5,키워드지표!$A$2:$A$84,0)),"") -> 108.1 | D5: =IFERROR(INDEX(키워드지표!$C$2:$C$84,MATCH(D$2&$A5,키워드지표!$A$2:$A$84,0)),"") -> 161 | E5: =IFERROR(INDEX(키워드지표!$C$2:$C$84,MATCH(E$2&$A5,키워드지표!$A$2:$A$84,0)),"") -> 83.8 | F5: =IFERROR(INDEX(키워드지표!$C$2:$C$84,MATCH(F$2&$A5,키워드지표!$A$2:$A$84,0)),"") -> 139.7 | G5: =IFERROR(INDEX(키워드지표!$C$2:$C$84,MATCH(G$2&$A5,키워드지표!$A$2:$A$84,0)),"") -> 233.8 | H5: =IFERROR(INDEX(키워드지표!$C$2:$C$84,MATCH(H$2&$A5,키워드지표!$A$2:$A$84,0)),"") -> 135.8 | I5: =SUM(B5:H5) -> 962.2
